Workbook
Name CSVPath: csv!$A$2

Sheet ipopt_output

Sheet averages
A1: =ipopt_output!A1 -> run | B1: =ipopt_output!B1 -> status | C1: =ipopt_output!C1 -> variables | D1: =ipopt_output!D1 -> equality_constraints | E1: =ipopt_output!E1 -> inequality_constraints | F1: =ipopt_output!F1 -> iterations | G1: =ipopt_output!G1 -> objective_unscaled | H1: =ipopt_output!H1 -> constraint_violation_unscaled | ... T1: =ipopt_output!T1 -> run_start_time | U1: num_runs
A2: {=INDEX(ipopt_output!A:A, (ROW()-2)*$U2+2)} -> cart_pole_swing_col3_py | B2: {=INDEX(ipopt_output!B:B, (ROW()-2)*$U2+2)} -> Optimal Solution Found. | C2: =IFERROR(AVERAGE(INDEX(ipopt_output!C:C, (ROW()-2)*$U2+2):INDEX(ipopt_output!C:C, (ROW()-2)*$U2 + $U2+1)), "") -> 900 | D2: =IFERROR(AVERAGE(INDEX(ipopt_output!D:D, (ROW()-2)*$U2+2):INDEX(ipopt_output!D:D, (ROW()-2)*$U2 + $U2+1)), "") -> 853 | E2: =IFERROR(AVERAGE(INDEX(ipopt_output!E:E, (ROW()-2)*$U2+2):INDEX(ipopt_output!E:E, (ROW()-2)*$U2 + $U2+1)), "") -> 50 | F2: =IFERROR(AVERAGE(INDEX(ipopt_output!F:F, (ROW()-2)*$U2+2):INDEX(ipopt_output!F:F, (ROW()-2)*$U2 + $U2+1)), "") -> 371 | G2: =IFERROR(AVERAGE(INDEX(ipopt_output!G:G, (ROW()-2)*$U2+2):INDEX(ipopt_output!G:G, (ROW()-2)*$U2 + $U2+1)), "") -> 1583.339 | H2: =IFERROR(AVERAGE(INDEX(ipopt_output!H:H, (ROW()-2)*$U2+2):INDEX(ipopt_output!H:H, (ROW()-2)*$U2 + $U2+1)), "") -> 1.6081358e-10 | I2: =IFERROR(AVERAGE(INDEX(ipopt_output!I:I, (ROW()-2)*$U2+2):INDEX(ipopt_output!I:I, (ROW()-2)*$U2 + $U2+1)), "") -> 1.014 | J2: =IFERROR(AVERAGE(INDEX(ipopt_output!J:J, (ROW()-2)*$U2+2):INDEX(ipopt_output!J:J, (ROW()-2)*$U2 + $U2+1)), "") -> 0.14125 | K2: =IFERROR(AVERAGE(INDEX(ipopt_output!K:K, (ROW()-2)*$U2+2):INDEX(ipopt_output!K:K, (ROW()-2)*$U2 + $U2+1)), "") -> 1.9838443 | L2: =IFERROR(AVERAGE(INDEX(ipopt_output!L:L, (ROW()-2)*$U2+2):INDEX(ipopt_output!L:L, (ROW()-2)*$U2 + $U2+1)), "") | M2: =IFERROR(AVERAGE(INDEX(ipopt_output!M:M, (ROW()-2)*$U2+2):INDEX(ipopt_output!M:M, (ROW()-2)*$U2 + $U2+1)), "") | N2: =IFERROR(AVERAGE(INDEX(ipopt_output!N:N, (ROW()-2)*$U2+2):INDEX(ipopt_output!N:N, (ROW()-2)*$U2 + $U2+1)), "") | O2: =IFERROR(AVERAGE(INDEX(ipopt_output!O:O, (ROW()-2)*$U2+2):INDEX(ipopt_output!O:O, (ROW()-2)*$U2 + $U2+1)), "") | P2: =IFERROR(AVERAGE(INDEX(ipopt_output!P:P, (ROW()-2)*$U2+2):INDEX(ipopt_output!P:P, (ROW()-2)*$U2 + $U2+1)), "") | Q2: =IFERROR(AVERAGE(INDEX(ipopt_output!Q:Q, (ROW()-2)*$U2+2):INDEX(ipopt_output!Q:Q, (ROW()-2)*$U2 + $U2+1)), "") | R2: =IFERROR(AVERAGE(INDEX(ipopt_output!R:R, (ROW()-2)*$U2+2):INDEX(ipopt_output!R:R, (ROW()-2)*$U2 + $U2+1)), "") -> 1.9838425 | S2: =IFERROR(AVERAGE(INDEX(ipopt_output!S:S, (ROW()-2)*$U2+2):INDEX(ipopt_output!S:S, (ROW()-2)*$U2 + $U2+1)), "") -> 20260407 | T2: =IFERROR(AVERAGE(INDEX(ipopt_output!T:T, (ROW()-2)*$U2+2):INDEX(ipopt_output!T:T, (ROW()-2)*$U2 + $U2+1)), "") -> 169857.75 | U2: =COUNTIF(ipopt_output!A:A, ipopt_output!A2) -> 4
A3: {=INDEX(ipopt_output!A:A, (ROW()-2)*$U3+2)} -> cart_pole_swing_col3_run | B3: {=INDEX(ipopt_output!B:B, (ROW()-2)*$U3+2)} -> Optimal Solution Found. | C3: =IFERROR(AVERAGE(INDEX(ipopt_output!C:C, (ROW()-2)*$U3+2):INDEX(ipopt_output!C:C, (ROW()-2)*$U3 + $U3+1)), "") -> 1197 | D3: =IFERROR(AVERAGE(INDEX(ipopt_output!D:D, (ROW()-2)*$U3+2):INDEX(ipopt_output!D:D, (ROW()-2)*$U3 + $U3+1)), "") -> 1150 | E3: =IFERROR(AVERAGE(INDEX(ipopt_output!E:E, (ROW()-2)*$U3+2):INDEX(ipopt_output!E:E, (ROW()-2)*$U3 + $U3+1)), "") -> 50 | F3: =IFERROR(AVERAGE(INDEX(ipopt_output!F:F, (ROW()-2)*$U3+2):INDEX(ipopt_output!F:F, (ROW()-2)*$U3 + $U3+1)), "") -> 409 | G3: =IFERROR(AVERAGE(INDEX(ipopt_output!G:G, (ROW()-2)*$U3+2):INDEX(ipopt_output!G:G, (ROW()-2)*$U3 + $U3+1)), "") -> 1921.3976 | H3: =IFERROR(AVERAGE(INDEX(ipopt_output!H:H, (ROW()-2)*$U3+2):INDEX(ipopt_output!H:H, (ROW()-2)*$U3 + $U3+1)), "") -> 2.172289e-10 | I3: =IFERROR(AVERAGE(INDEX(ipopt_output!I:I, (ROW()-2)*$U3+2):INDEX(ipopt_output!I:I, (ROW()-2)*$U3 + $U3+1)), "") -> 3.2855 | J3: =IFERROR(AVERAGE(INDEX(ipopt_output!J:J, (ROW()-2)*$U3+2):INDEX(ipopt_output!J:J, (ROW()-2)*$U3 + $U3+1)), "") -> 0.729 | K3: =IFERROR(AVERAGE(INDEX(ipopt_output!K:K, (ROW()-2)*$U3+2):INDEX(ipopt_output!K:K, (ROW()-2)*$U3 + $U3+1)), "") | L3: =IFERROR(AVERAGE(INDEX(ipopt_output!L:L, (ROW()-2)*$U3+2):INDEX(ipopt_output!L:L, (ROW()-2)*$U3 + $U3+1)), "") -> 0.05470625 | M3: =IFERROR(AVERAGE(INDEX(ipopt_output!M:M, (ROW()-2)*$U3+2):INDEX(ipopt_output!M:M, (ROW()-2)*$U3 + $U3+1)), "") -> 4.0659635 | N3: =IFERROR(AVERAGE(INDEX(ipopt_output!N:N, (ROW()-2)*$U3+2):INDEX(ipopt_output!N:N, (ROW()-2)*$U3 + $U3+1)), "") -> 19139 | O3: =IFERROR(AVERAGE(INDEX(ipopt_output!O:O, (ROW()-2)*$U3+2):INDEX(ipopt_output!O:O, (ROW()-2)*$U3 + $U3+1)), "") -> 1197 | P3: =IFERROR(AVERAGE(INDEX(ipopt_output!P:P, (ROW()-2)*$U3+2):INDEX(ipopt_output!P:P, (ROW()-2)*$U3 + $U3+1)), "") -> 19447 | Q3: =IFERROR(AVERAGE(INDEX(ipopt_output!Q:Q, (ROW()-2)*$U3+2):INDEX(ipopt_output!Q:Q, (ROW()-2)*$U3 + $U3+1)), "") -> 1200 | R3: =IFERROR(AVERAGE(INDEX(ipopt_output!R:R, (ROW()-2)*$U3+2):INDEX(ipopt_output!R:R, (ROW()-2)*$U3 + $U3+1)), "") -> 4.12067 | S3: =IFERROR(AVERAGE(INDEX(ipopt_output!S:S, (ROW()-2)*$U3+2):INDEX(ipopt_output!S:S, (ROW()-2)*$U3 + $U3+1)), "") -> 20260407 | T3: =IFERROR(AVERAGE(INDEX(ipopt_output!T:T, (ROW()-2)*$U3+2):INDEX(ipopt_output!T:T, (ROW()-2)*$U3 + $U3+1)), "") -> 161448.75 | U3: {=COUNTIF(ipopt_output!A:A,INDEX(ipopt_output!A:A,SUM(U$2:U2)+2))} -> 4
A4: {=INDEX(ipopt_output!A:A, (ROW()-2)*$U4+2)} -> cart_pole_swing_rk1_py | B4: {=INDEX(ipopt_output!B:B, (ROW()-2)*$U4+2)} -> Optimal Solution Found. | C4: =IFERROR(AVERAGE(INDEX(ipopt_output!C:C, (ROW()-2)*$U4+2):INDEX(ipopt_output!C:C, (ROW()-2)*$U4 + $U4+1)), "") -> 300 | D4: =IFERROR(AVERAGE(INDEX(ipopt_output!D:D, (ROW()-2)*$U4+2):INDEX(ipopt_output!D:D, (ROW()-2)*$U4 + $U4+1)), "") -> 253 | E4: =IFERROR(AVERAGE(INDEX(ipopt_output!E:E, (ROW()-2)*$U4+2):INDEX(ipopt_output!E:E, (ROW()-2)*$U4 + $U4+1)), "") -> 50 | F4: =IFERROR(AVERAGE(INDEX(ipopt_output!F:F, (ROW()-2)*$U4+2):INDEX(ipopt_output!F:F, (ROW()-2)*$U4 + $U4+1)), "") -> 371 | G4: =IFERROR(AVERAGE(INDEX(ipopt_output!G:G, (ROW()-2)*$U4+2):INDEX(ipopt_output!G:G, (ROW()-2)*$U4 + $U4+1)), "") -> 1583.339 | H4: =IFERROR(AVERAGE(INDEX(ipopt_output!H:H, (ROW()-2)*$U4+2):INDEX(ipopt_output!H:H, (ROW()-2)*$U4 + $U4+1)), "") -> 1.6081536e-10 | I4: =IFERROR(AVERAGE(INDEX(ipopt_output!I:I, (ROW()-2)*$U4+2):INDEX(ipopt_output!I:I, (ROW()-2)*$U4 + $U4+1)), "") -> 0.565 | J4: =IFERROR(AVERAGE(INDEX(ipopt_output!J:J, (ROW()-2)*$U4+2):INDEX(ipopt_output!J:J, (ROW()-2)*$U4 + $U4+1)), "") -> 0.087 | K4: =IFERROR(AVERAGE(INDEX(ipopt_output!K:K, (ROW()-2)*$U4+2):INDEX(ipopt_output!K:K, (ROW()-2)*$U4 + $U4+1)), "") -> 1.1868055 | L4: =IFERROR(AVERAGE(INDEX(ipopt_output!L:L, (ROW()-2)*$U4+2):INDEX(ipopt_output!L:L, (ROW()-2)*$U4 + $U4+1)), "") | M4: =IFERROR(AVERAGE(INDEX(ipopt_output!M:M, (ROW()-2)*$U4+2):INDEX(ipopt_output!M:M, (ROW()-2)*$U4 + $U4+1)), "") | N4: =IFERROR(AVERAGE(INDEX(ipopt_output!N:N, (ROW()-2)*$U4+2):INDEX(ipopt_output!N:N, (ROW()-2)*$U4 + $U4+1)), "") | O4: =IFERROR(AVERAGE(INDEX(ipopt_output!O:O, (ROW()-2)*$U4+2):INDEX(ipopt_output!O:O, (ROW()-2)*$U4 + $U4+1)), "") | P4: =IFERROR(AVERAGE(INDEX(ipopt_output!P:P, (ROW()-2)*$U4+2):INDEX(ipopt_output!P:P, (ROW()-2)*$U4 + $U4+1)), "") | Q4: =IFERROR(AVERAGE(INDEX(ipopt_output!Q:Q, (ROW()-2)*$U4+2):INDEX(ipopt_output!Q:Q, (ROW()-2)*$U4 + $U4+1)), "") | R4: =IFERROR(AVERAGE(INDEX(ipopt_output!R:R, (ROW()-2)*$U4+2):INDEX(ipopt_output!R:R, (ROW()-2)*$U4 + $U4+1)), "") -> 1.186805 | S4: =IFERROR(AVERAGE(INDEX(ipopt_output!S:S, (ROW()-2)*$U4+2):INDEX(ipopt_output!S:S, (ROW()-2)*$U4 + $U4+1)), "") -> 20260407 | T4: =IFERROR(AVERAGE(INDEX(ipopt_output!T:T, (ROW()-2)*$U4+2):INDEX(ipopt_output!T:T, (ROW()-2)*$U4 + $U4+1)), "") -> 169857.75 | U4: {=COUNTIF(ipopt_output!A:A,INDEX(ipopt_output!A:A,SUM(U$2:U3)+2))} -> 4
A5: {=INDEX(ipopt_output!A:A, (ROW()-2)*$U5+2)} -> cart_pole_swing_rk1_run | B5: {=INDEX(ipopt_output!B:B, (ROW()-2)*$U5+2)} -> Optimal Solution Found. | C5: =IFERROR(AVERAGE(INDEX(ipopt_output!C:C, (ROW()-2)*$U5+2):INDEX(ipopt_output!C:C, (ROW()-2)*$U5 + $U5+1)), "") -> 295 | D5: =IFERROR(AVERAGE(INDEX(ipopt_output!D:D, (ROW()-2)*$U5+2):INDEX(ipopt_output!D:D, (ROW()-2)*$U5 + $U5+1)), "") -> 248 | E5: =IFERROR(AVERAGE(INDEX(ipopt_output!E:E, (ROW()-2)*$U5+2):INDEX(ipopt_output!E:E, (ROW()-2)*$U5 + $U5+1)), "") -> 50 | F5: =IFERROR(AVERAGE(INDEX(ipopt_output!F:F, (ROW()-2)*$U5+2):INDEX(ipopt_output!F:F, (ROW()-2)*$U5 + $U5+1)), "") -> 371 | G5: =IFERROR(AVERAGE(INDEX(ipopt_output!G:G, (ROW()-2)*$U5+2):INDEX(ipopt_output!G:G, (ROW()-2)*$U5 + $U5+1)), "") -> 1583.339 | H5: =IFERROR(AVERAGE(INDEX(ipopt_output!H:H, (ROW()-2)*$U5+2):INDEX(ipopt_output!H:H, (ROW()-2)*$U5 + $U5+1)), "") -> 1.6081003e-10 | I5: =IFERROR(AVERAGE(INDEX(ipopt_output!I:I, (ROW()-2)*$U5+2):INDEX(ipopt_output!I:I, (ROW()-2)*$U5 + $U5+1)), "") -> 1.28025 | J5: =IFERROR(AVERAGE(INDEX(ipopt_output!J:J, (ROW()-2)*$U5+2):INDEX(ipopt_output!J:J, (ROW()-2)*$U5 + $U5+1)), "") -> 0.5705 | K5: =IFERROR(AVERAGE(INDEX(ipopt_output!K:K, (ROW()-2)*$U5+2):INDEX(ipopt_output!K:K, (ROW()-2)*$U5 + $U5+1)), "") | L5: =IFERROR(AVERAGE(INDEX(ipopt_output!L:L, (ROW()-2)*$U5+2):INDEX(ipopt_output!L:L, (ROW()-2)*$U5 + $U5+1)), "") -> 0.05135475 | M5: =IFERROR(AVERAGE(INDEX(ipopt_output!M:M, (ROW()-2)*$U5+2):INDEX(ipopt_output!M:M, (ROW()-2)*$U5 + $U5+1)), "") -> 2.0128268 | N5: =IFERROR(AVERAGE(INDEX(ipopt_output!N:N, (ROW()-2)*$U5+2):INDEX(ipopt_output!N:N, (ROW()-2)*$U5 + $U5+1)), "") -> 16889 | O5: =IFERROR(AVERAGE(INDEX(ipopt_output!O:O, (ROW()-2)*$U5+2):INDEX(ipopt_output!O:O, (ROW()-2)*$U5 + $U5+1)), "") -> 295 | P5: =IFERROR(AVERAGE(INDEX(ipopt_output!P:P, (ROW()-2)*$U5+2):INDEX(ipopt_output!P:P, (ROW()-2)*$U5 + $U5+1)), "") -> 17197 | Q5: =IFERROR(AVERAGE(INDEX(ipopt_output!Q:Q, (ROW()-2)*$U5+2):INDEX(ipopt_output!Q:Q, (ROW()-2)*$U5 + $U5+1)), "") -> 298 | R5: =IFERROR(AVERAGE(INDEX(ipopt_output!R:R, (ROW()-2)*$U5+2):INDEX(ipopt_output!R:R, (ROW()-2)*$U5 + $U5+1)), "") -> 2.06418 | S5: =IFERROR(AVERAGE(INDEX(ipopt_output!S:S, (ROW()-2)*$U5+2):INDEX(ipopt_output!S:S, (ROW()-2)*$U5 + $U5+1)), "") -> 20260407 | T5: =IFERROR(AVERAGE(INDEX(ipopt_output!T:T, (ROW()-2)*$U5+2):INDEX(ipopt_output!T:T, (ROW()-2)*$U5 + $U5+1)), "") -> 161448.75 | U5: {=COUNTIF(ipopt_output!A:A,INDEX(ipopt_output!A:A,SUM(U$2:U4)+2))} -> 4
A6: {=INDEX(ipopt_output!A:A, (ROW()-2)*$U6+2)} -> cart_pole_swing_rk4_py | B6: {=INDEX(ipopt_output!B:B, (ROW()-2)*$U6+2)} -> Optimal Solution Found. | C6: =IFERROR(AVERAGE(INDEX(ipopt_output!C:C, (ROW()-2)*$U6+2):INDEX(ipopt_output!C:C, (ROW()-2)*$U6 + $U6+1)), "") -> 300 | D6: =IFERROR(AVERAGE(INDEX(ipopt_output!D:D, (ROW()-2)*$U6+2):INDEX(ipopt_output!D:D, (ROW()-2)*$U6 + $U6+1)), "") -> 253 | E6: =IFERROR(AVERAGE(INDEX(ipopt_output!E:E, (ROW()-2)*$U6+2):INDEX(ipopt_output!E:E, (ROW()-2)*$U6 + $U6+1)), "") -> 50 | F6: =IFERROR(AVERAGE(INDEX(ipopt_output!F:F, (ROW()-2)*$U6+2):INDEX(ipopt_output!F:F, (ROW()-2)*$U6 + $U6+1)), "") -> 411 | G6: =IFERROR(AVERAGE(INDEX(ipopt_output!G:G, (ROW()-2)*$U6+2):INDEX(ipopt_output!G:G, (ROW()-2)*$U6 + $U6+1)), "") -> 1921.3976 | H6: =IFERROR(AVERAGE(INDEX(ipopt_output!H:H, (ROW()-2)*$U6+2):INDEX(ipopt_output!H:H, (ROW()-2)*$U6 + $U6+1)), "") -> 2.1748114e-10 | I6: =IFERROR(AVERAGE(INDEX(ipopt_output!I:I, (ROW()-2)*$U6+2):INDEX(ipopt_output!I:I, (ROW()-2)*$U6 + $U6+1)), "") -> 0.6045 | J6: =IFERROR(AVERAGE(INDEX(ipopt_output!J:J, (ROW()-2)*$U6+2):INDEX(ipopt_output!J:J, (ROW()-2)*$U6 + $U6+1)), "") -> 0.103 | K6: =IFERROR(AVERAGE(INDEX(ipopt_output!K:K, (ROW()-2)*$U6+2):INDEX(ipopt_output!K:K, (ROW()-2)*$U6 + $U6+1)), "") -> 1.2900225 | L6: =IFERROR(AVERAGE(INDEX(ipopt_output!L:L, (ROW()-2)*$U6+2):INDEX(ipopt_output!L:L, (ROW()-2)*$U6 + $U6+1)), "") | M6: =IFERROR(AVERAGE(INDEX(ipopt_output!M:M, (ROW()-2)*$U6+2):INDEX(ipopt_output!M:M, (ROW()-2)*$U6 + $U6+1)), "") | N6: =IFERROR(AVERAGE(INDEX(ipopt_output!N:N, (ROW()-2)*$U6+2):INDEX(ipopt_output!N:N, (ROW()-2)*$U6 + $U6+1)), "") | O6: =IFERROR(AVERAGE(INDEX(ipopt_output!O:O, (ROW()-2)*$U6+2):INDEX(ipopt_output!O:O, (ROW()-2)*$U6 + $U6+1)), "") | P6: =IFERROR(AVERAGE(INDEX(ipopt_output!P:P, (ROW()-2)*$U6+2):INDEX(ipopt_output!P:P, (ROW()-2)*$U6 + $U6+1)), "") | Q6: =IFERROR(AVERAGE(INDEX(ipopt_output!Q:Q, (ROW()-2)*$U6+2):INDEX(ipopt_output!Q:Q, (ROW()-2)*$U6 + $U6+1)), "") | R6: =IFERROR(AVERAGE(INDEX(ipopt_output!R:R, (ROW()-2)*$U6+2):INDEX(ipopt_output!R:R, (ROW()-2)*$U6 + $U6+1)), "") -> 1.2900225 | S6: =IFERROR(AVERAGE(INDEX(ipopt_output!S:S, (ROW()-2)*$U6+2):INDEX(ipopt_output!S:S, (ROW()-2)*$U6 + $U6+1)), "") -> 20260407 | T6: =IFERROR(AVERAGE(INDEX(ipopt_output!T:T, (ROW()-2)*$U6+2):INDEX(ipopt_output!T:T, (ROW()-2)*$U6 + $U6+1)), "") -> 169857.75 | U6: {=COUNTIF(ipopt_output!A:A,INDEX(ipopt_output!A:A,SUM(U$2:U5)+2))} -> 4
A7: {=INDEX(ipopt_output!A:A, (ROW()-2)*$U7+2)} -> cart_pole_swing_rk4_run | B7: {=INDEX(ipopt_output!B:B, (ROW()-2)*$U7+2)} -> Optimal Solution Found. | C7: =IFERROR(AVERAGE(INDEX(ipopt_output!C:C, (ROW()-2)*$U7+2):INDEX(ipopt_output!C:C, (ROW()-2)*$U7 + $U7+1)), "") -> 1195 | D7: =IFERROR(AVERAGE(INDEX(ipopt_output!D:D, (ROW()-2)*$U7+2):INDEX(ipopt_output!D:D, (ROW()-2)*$U7 + $U7+1)), "") -> 1148 | E7: =IFERROR(AVERAGE(INDEX(ipopt_output!E:E, (ROW()-2)*$U7+2):INDEX(ipopt_output!E:E, (ROW()-2)*$U7 + $U7+1)), "") -> 50 | F7: =IFERROR(AVERAGE(INDEX(ipopt_output!F:F, (ROW()-2)*$U7+2):INDEX(ipopt_output!F:F, (ROW()-2)*$U7 + $U7+1)), "") -> 409 | G7: =IFERROR(AVERAGE(INDEX(ipopt_output!G:G, (ROW()-2)*$U7+2):INDEX(ipopt_output!G:G, (ROW()-2)*$U7 + $U7+1)), "") -> 1921.3976 | H7: =IFERROR(AVERAGE(INDEX(ipopt_output!H:H, (ROW()-2)*$U7+2):INDEX(ipopt_output!H:H, (ROW()-2)*$U7 + $U7+1)), "") -> 2.1722713e-10 | I7: =IFERROR(AVERAGE(INDEX(ipopt_output!I:I, (ROW()-2)*$U7+2):INDEX(ipopt_output!I:I, (ROW()-2)*$U7 + $U7+1)), "") -> 3.53575 | J7: =IFERROR(AVERAGE(INDEX(ipopt_output!J:J, (ROW()-2)*$U7+2):INDEX(ipopt_output!J:J, (ROW()-2)*$U7 + $U7+1)), "") -> 0.7225 | K7: =IFERROR(AVERAGE(INDEX(ipopt_output!K:K, (ROW()-2)*$U7+2):INDEX(ipopt_output!K:K, (ROW()-2)*$U7 + $U7+1)), "") | L7: =IFERROR(AVERAGE(INDEX(ipopt_output!L:L, (ROW()-2)*$U7+2):INDEX(ipopt_output!L:L, (ROW()-2)*$U7 + $U7+1)), "") -> 0.05396875 | M7: =IFERROR(AVERAGE(INDEX(ipopt_output!M:M, (ROW()-2)*$U7+2):INDEX(ipopt_output!M:M, (ROW()-2)*$U7 + $U7+1)), "") -> 4.4135403 | N7: =IFERROR(AVERAGE(INDEX(ipopt_output!N:N, (ROW()-2)*$U7+2):INDEX(ipopt_output!N:N, (ROW()-2)*$U7 + $U7+1)), "") -> 19139 | O7: =IFERROR(AVERAGE(INDEX(ipopt_output!O:O, (ROW()-2)*$U7+2):INDEX(ipopt_output!O:O, (ROW()-2)*$U7 + $U7+1)), "") -> 1195 | P7: =IFERROR(AVERAGE(INDEX(ipopt_output!P:P, (ROW()-2)*$U7+2):INDEX(ipopt_output!P:P, (ROW()-2)*$U7 + $U7+1)), "") -> 19447 | Q7: =IFERROR(AVERAGE(INDEX(ipopt_output!Q:Q, (ROW()-2)*$U7+2):INDEX(ipopt_output!Q:Q, (ROW()-2)*$U7 + $U7+1)), "") -> 1198 | R7: =IFERROR(AVERAGE(INDEX(ipopt_output!R:R, (ROW()-2)*$U7+2):INDEX(ipopt_output!R:R, (ROW()-2)*$U7 + $U7+1)), "") -> 4.4675075 | S7: =IFERROR(AVERAGE(INDEX(ipopt_output!S:S, (ROW()-2)*$U7+2):INDEX(ipopt_output!S:S, (ROW()-2)*$U7 + $U7+1)), "") -> 20260407 | T7: =IFERROR(AVERAGE(INDEX(ipopt_output!T:T, (ROW()-2)*$U7+2):INDEX(ipopt_output!T:T, (ROW()-2)*$U7 + $U7+1)), "") -> 161448.75 | U7: {=COUNTIF(ipopt_output!A:A,INDEX(ipopt_output!A:A,SUM(U$2:U6)+2))} -> 4
A8: {=INDEX(ipopt_output!A:A, (ROW()-2)*$U8+2)} -> spot_jump_twist_col3_py | B8: {=INDEX(ipopt_output!B:B, (ROW()-2)*$U8+2)} -> Converged to a point of local infeasibility. Problem may be infeasible. | C8: =IFERROR(AVERAGE(INDEX(ipopt_output!C:C, (ROW()-2)*$U8+2):INDEX(ipopt_output!C:C, (ROW()-2)*$U8 + $U8+1)), "") -> 8950 | D8: =IFERROR(AVERAGE(INDEX(ipopt_output!D:D, (ROW()-2)*$U8+2):INDEX(ipopt_output!D:D, (ROW()-2)*$U8 + $U8+1)), "") -> 8337 | E8: =IFERROR(AVERAGE(INDEX(ipopt_output!E:E, (ROW()-2)*$U8+2):INDEX(ipopt_output!E:E, (ROW()-2)*$U8 + $U8+1)), "") -> 1180 | F8: =IFERROR(AVERAGE(INDEX(ipopt_output!F:F, (ROW()-2)*$U8+2):INDEX(ipopt_output!F:F, (ROW()-2)*$U8 + $U8+1)), "") -> 493 | G8: =IFERROR(AVERAGE(INDEX(ipopt_output!G:G, (ROW()-2)*$U8+2):INDEX(ipopt_output!G:G, (ROW()-2)*$U8 + $U8+1)), "") -> 16947.153 | H8: =IFERROR(AVERAGE(INDEX(ipopt_output!H:H, (ROW()-2)*$U8+2):INDEX(ipopt_output!H:H, (ROW()-2)*$U8 + $U8+1)), "") -> 0.01241105 | I8: =IFERROR(AVERAGE(INDEX(ipopt_output!I:I, (ROW()-2)*$U8+2):INDEX(ipopt_output!I:I, (ROW()-2)*$U8 + $U8+1)), "") -> 75.742 | J8: =IFERROR(AVERAGE(INDEX(ipopt_output!J:J, (ROW()-2)*$U8+2):INDEX(ipopt_output!J:J, (ROW()-2)*$U8 + $U8+1)), "") -> 17.43475 | K8: =IFERROR(AVERAGE(INDEX(ipopt_output!K:K, (ROW()-2)*$U8+2):INDEX(ipopt_output!K:K, (ROW()-2)*$U8 + $U8+1)), "") -> 115.15039 | L8: =IFERROR(AVERAGE(INDEX(ipopt_output!L:L, (ROW()-2)*$U8+2):INDEX(ipopt_output!L:L, (ROW()-2)*$U8 + $U8+1)), "") | M8: =IFERROR(AVERAGE(INDEX(ipopt_output!M:M, (ROW()-2)*$U8+2):INDEX(ipopt_output!M:M, (ROW()-2)*$U8 + $U8+1)), "") | N8: =IFERROR(AVERAGE(INDEX(ipopt_output!N:N, (ROW()-2)*$U8+2):INDEX(ipopt_output!N:N, (ROW()-2)*$U8 + $U8+1)), "") | O8: =IFERROR(AVERAGE(INDEX(ipopt_output!O:O, (ROW()-2)*$U8+2):INDEX(ipopt_output!O:O, (ROW()-2)*$U8 + $U8+1)), "") | P8: =IFERROR(AVERAGE(INDEX(ipopt_output!P:P, (ROW()-2)*$U8+2):INDEX(ipopt_output!P:P, (ROW()-2)*$U8 + $U8+1)), "") | Q8: =IFERROR(AVERAGE(INDEX(ipopt_output!Q:Q, (ROW()-2)*$U8+2):INDEX(ipopt_output!Q:Q, (ROW()-2)*$U8 + $U8+1)), "") | R8: =IFERROR(AVERAGE(INDEX(ipopt_output!R:R, (ROW()-2)*$U8+2):INDEX(ipopt_output!R:R, (ROW()-2)*$U8 + $U8+1)), "") -> 115.1505 | S8: =IFERROR(AVERAGE(INDEX(ipopt_output!S:S, (ROW()-2)*$U8+2):INDEX(ipopt_output!S:S, (ROW()-2)*$U8 + $U8+1)), "") -> 20260407 | T8: =IFERROR(AVERAGE(INDEX(ipopt_output!T:T, (ROW()-2)*$U8+2):INDEX(ipopt_output!T:T, (ROW()-2)*$U8 + $U8+1)), "") -> 169857.75 | U8: {=COUNTIF(ipopt_output!A:A,INDEX(ipopt_output!A:A,SUM(U$2:U7)+2))} -> 4
A9: {=INDEX(ipopt_output!A:A, (ROW()-2)*$U9+2)} -> spot_jump_twist_col3_run | B9: {=INDEX(ipopt_output!B:B, (ROW()-2)*$U9+2)} -> Optimal Solution Found. | C9: =IFERROR(AVERAGE(INDEX(ipopt_output!C:C, (ROW()-2)*$U9+2):INDEX(ipopt_output!C:C, (ROW()-2)*$U9 + $U9+1)), "") -> 12454 | D9: =IFERROR(AVERAGE(INDEX(ipopt_output!D:D, (ROW()-2)*$U9+2):INDEX(ipopt_output!D:D, (ROW()-2)*$U9 + $U9+1)), "") -> 11828 | E9: =IFERROR(AVERAGE(INDEX(ipopt_output!E:E, (ROW()-2)*$U9+2):INDEX(ipopt_output!E:E, (ROW()-2)*$U9 + $U9+1)), "") -> 1080 | F9: =IFERROR(AVERAGE(INDEX(ipopt_output!F:F, (ROW()-2)*$U9+2):INDEX(ipopt_output!F:F, (ROW()-2)*$U9 + $U9+1)), "") -> 208 | G9: =IFERROR(AVERAGE(INDEX(ipopt_output!G:G, (ROW()-2)*$U9+2):INDEX(ipopt_output!G:G, (ROW()-2)*$U9 + $U9+1)), "") -> 55592.036 | H9: =IFERROR(AVERAGE(INDEX(ipopt_output!H:H, (ROW()-2)*$U9+2):INDEX(ipopt_output!H:H, (ROW()-2)*$U9 + $U9+1)), "") -> 1.0401283e-05 | I9: =IFERROR(AVERAGE(INDEX(ipopt_output!I:I, (ROW()-2)*$U9+2):INDEX(ipopt_output!I:I, (ROW()-2)*$U9 + $U9+1)), "") -> 266.3415 | J9: =IFERROR(AVERAGE(INDEX(ipopt_output!J:J, (ROW()-2)*$U9+2):INDEX(ipopt_output!J:J, (ROW()-2)*$U9 + $U9+1)), "") -> 600.7925 | K9: =IFERROR(AVERAGE(INDEX(ipopt_output!K:K, (ROW()-2)*$U9+2):INDEX(ipopt_output!K:K, (ROW()-2)*$U9 + $U9+1)), "") | L9: =IFERROR(AVERAGE(INDEX(ipopt_output!L:L, (ROW()-2)*$U9+2):INDEX(ipopt_output!L:L, (ROW()-2)*$U9 + $U9+1)), "") -> 2.0476298 | M9: =IFERROR(AVERAGE(INDEX(ipopt_output!M:M, (ROW()-2)*$U9+2):INDEX(ipopt_output!M:M, (ROW()-2)*$U9 + $U9+1)), "") -> 877.6255 | N9: =IFERROR(AVERAGE(INDEX(ipopt_output!N:N, (ROW()-2)*$U9+2):INDEX(ipopt_output!N:N, (ROW()-2)*$U9 + $U9+1)), "") -> 309215 | O9: =IFERROR(AVERAGE(INDEX(ipopt_output!O:O, (ROW()-2)*$U9+2):INDEX(ipopt_output!O:O, (ROW()-2)*$U9 + $U9+1)), "") -> 12454 | P9: =IFERROR(AVERAGE(INDEX(ipopt_output!P:P, (ROW()-2)*$U9+2):INDEX(ipopt_output!P:P, (ROW()-2)*$U9 + $U9+1)), "") -> 318599 | Q9: =IFERROR(AVERAGE(INDEX(ipopt_output!Q:Q, (ROW()-2)*$U9+2):INDEX(ipopt_output!Q:Q, (ROW()-2)*$U9 + $U9+1)), "") -> 12908 | R9: =IFERROR(AVERAGE(INDEX(ipopt_output!R:R, (ROW()-2)*$U9+2):INDEX(ipopt_output!R:R, (ROW()-2)*$U9 + $U9+1)), "") -> 879.67325 | S9: =IFERROR(AVERAGE(INDEX(ipopt_output!S:S, (ROW()-2)*$U9+2):INDEX(ipopt_output!S:S, (ROW()-2)*$U9 + $U9+1)), "") -> 20260407 | T9: =IFERROR(AVERAGE(INDEX(ipopt_output!T:T, (ROW()-2)*$U9+2):INDEX(ipopt_output!T:T, (ROW()-2)*$U9 + $U9+1)), "") -> 161448.75 | U9: {=COUNTIF(ipopt_output!A:A,INDEX(ipopt_output!A:A,SUM(U$2:U8)+2))} -> 4
A10: {=INDEX(ipopt_output!A:A, (ROW()-2)*$U10+2)} -> spot_jump_twist_rk1_py | B10: {=INDEX(ipopt_output!B:B, (ROW()-2)*$U10+2)} -> Converged to a point of local infeasibility. Problem may be infeasible. | C10: =IFERROR(AVERAGE(INDEX(ipopt_output!C:C, (ROW()-2)*$U10+2):INDEX(ipopt_output!C:C, (ROW()-2)*$U10 + $U10+1)), "") -> 3400 | D10: =IFERROR(AVERAGE(INDEX(ipopt_output!D:D, (ROW()-2)*$U10+2):INDEX(ipopt_output!D:D, (ROW()-2)*$U10 + $U10+1)), "") -> 2787 | E10: =IFERROR(AVERAGE(INDEX(ipopt_output!E:E, (ROW()-2)*$U10+2):INDEX(ipopt_output!E:E, (ROW()-2)*$U10 + $U10+1)), "") -> 1180 | F10: =IFERROR(AVERAGE(INDEX(ipopt_output!F:F, (ROW()-2)*$U10+2):INDEX(ipopt_output!F:F, (ROW()-2)*$U10 + $U10+1)), "") -> 398 | G10: =IFERROR(AVERAGE(INDEX(ipopt_output!G:G, (ROW()-2)*$U10+2):INDEX(ipopt_output!G:G, (ROW()-2)*$U10 + $U10+1)), "") -> 19921.462 | H10: =IFERROR(AVERAGE(INDEX(ipopt_output!H:H, (ROW()-2)*$U10+2):INDEX(ipopt_output!H:H, (ROW()-2)*$U10 + $U10+1)), "") -> 0.012054749 | I10: =IFERROR(AVERAGE(INDEX(ipopt_output!I:I, (ROW()-2)*$U10+2):INDEX(ipopt_output!I:I, (ROW()-2)*$U10 + $U10+1)), "") -> 81.297 | J10: =IFERROR(AVERAGE(INDEX(ipopt_output!J:J, (ROW()-2)*$U10+2):INDEX(ipopt_output!J:J, (ROW()-2)*$U10 + $U10+1)), "") -> 12.34625 | K10: =IFERROR(AVERAGE(INDEX(ipopt_output!K:K, (ROW()-2)*$U10+2):INDEX(ipopt_output!K:K, (ROW()-2)*$U10 + $U10+1)), "") -> 114.14776 | L10: =IFERROR(AVERAGE(INDEX(ipopt_output!L:L, (ROW()-2)*$U10+2):INDEX(ipopt_output!L:L, (ROW()-2)*$U10 + $U10+1)), "") | M10: =IFERROR(AVERAGE(INDEX(ipopt_output!M:M, (ROW()-2)*$U10+2):INDEX(ipopt_output!M:M, (ROW()-2)*$U10 + $U10+1)), "") | N10: =IFERROR(AVERAGE(INDEX(ipopt_output!N:N, (ROW()-2)*$U10+2):INDEX(ipopt_output!N:N, (ROW()-2)*$U10 + $U10+1)), "") | O10: =IFERROR(AVERAGE(INDEX(ipopt_output!O:O, (ROW()-2)*$U10+2):INDEX(ipopt_output!O:O, (ROW()-2)*$U10 + $U10+1)), "") | P10: =IFERROR(AVERAGE(INDEX(ipopt_output!P:P, (ROW()-2)*$U10+2):INDEX(ipopt_output!P:P, (ROW()-2)*$U10 + $U10+1)), "") | Q10: =IFERROR(AVERAGE(INDEX(ipopt_output!Q:Q, (ROW()-2)*$U10+2):INDEX(ipopt_output!Q:Q, (ROW()-2)*$U10 + $U10+1)), "") | R10: =IFERROR(AVERAGE(INDEX(ipopt_output!R:R, (ROW()-2)*$U10+2):INDEX(ipopt_output!R:R, (ROW()-2)*$U10 + $U10+1)), "") -> 114.14775 | S10: =IFERROR(AVERAGE(INDEX(ipopt_output!S:S, (ROW()-2)*$U10+2):INDEX(ipopt_output!S:S, (ROW()-2)*$U10 + $U10+1)), "") -> 20260407 | T10: =IFERROR(AVERAGE(INDEX(ipopt_output!T:T, (ROW()-2)*$U10+2):INDEX(ipopt_output!T:T, (ROW()-2)*$U10 + $U10+1)), "") -> 169857.75 | U10: {=COUNTIF(ipopt_output!A:A,INDEX(ipopt_output!A:A,SUM(U$2:U9)+2))} -> 4
A11: {=INDEX(ipopt_output!A:A, (ROW()-2)*$U11+2)} -> spot_jump_twist_rk1_run | B11: {=INDEX(ipopt_output!B:B, (ROW()-2)*$U11+2)} -> Optimal Solution Found. | C11: =IFERROR(AVERAGE(INDEX(ipopt_output!C:C, (ROW()-2)*$U11+2):INDEX(ipopt_output!C:C, (ROW()-2)*$U11 + $U11+1)), "") -> 3106 | D11: =IFERROR(AVERAGE(INDEX(ipopt_output!D:D, (ROW()-2)*$U11+2):INDEX(ipopt_output!D:D, (ROW()-2)*$U11 + $U11+1)), "") -> 2480 | E11: =IFERROR(AVERAGE(INDEX(ipopt_output!E:E, (ROW()-2)*$U11+2):INDEX(ipopt_output!E:E, (ROW()-2)*$U11 + $U11+1)), "") -> 1080 | F11: =IFERROR(AVERAGE(INDEX(ipopt_output!F:F, (ROW()-2)*$U11+2):INDEX(ipopt_output!F:F, (ROW()-2)*$U11 + $U11+1)), "") -> 146 | G11: =IFERROR(AVERAGE(INDEX(ipopt_output!G:G, (ROW()-2)*$U11+2):INDEX(ipopt_output!G:G, (ROW()-2)*$U11 + $U11+1)), "") -> 14277.069 | H11: =IFERROR(AVERAGE(INDEX(ipopt_output!H:H, (ROW()-2)*$U11+2):INDEX(ipopt_output!H:H, (ROW()-2)*$U11 + $U11+1)), "") -> 1.1096563e-07 | I11: =IFERROR(AVERAGE(INDEX(ipopt_output!I:I, (ROW()-2)*$U11+2):INDEX(ipopt_output!I:I, (ROW()-2)*$U11 + $U11+1)), "") -> 43.6645 | J11: =IFERROR(AVERAGE(INDEX(ipopt_output!J:J, (ROW()-2)*$U11+2):INDEX(ipopt_output!J:J, (ROW()-2)*$U11 + $U11+1)), "") -> 421.62725 | K11: =IFERROR(AVERAGE(INDEX(ipopt_output!K:K, (ROW()-2)*$U11+2):INDEX(ipopt_output!K:K, (ROW()-2)*$U11 + $U11+1)), "") | L11: =IFERROR(AVERAGE(INDEX(ipopt_output!L:L, (ROW()-2)*$U11+2):INDEX(ipopt_output!L:L, (ROW()-2)*$U11 + $U11+1)), "") -> 1.9194953 | M11: =IFERROR(AVERAGE(INDEX(ipopt_output!M:M, (ROW()-2)*$U11+2):INDEX(ipopt_output!M:M, (ROW()-2)*$U11 + $U11+1)), "") -> 468.29927 | N11: =IFERROR(AVERAGE(INDEX(ipopt_output!N:N, (ROW()-2)*$U11+2):INDEX(ipopt_output!N:N, (ROW()-2)*$U11 + $U11+1)), "") -> 288365 | O11: =IFERROR(AVERAGE(INDEX(ipopt_output!O:O, (ROW()-2)*$U11+2):INDEX(ipopt_output!O:O, (ROW()-2)*$U11 + $U11+1)), "") -> 3106 | P11: =IFERROR(AVERAGE(INDEX(ipopt_output!P:P, (ROW()-2)*$U11+2):INDEX(ipopt_output!P:P, (ROW()-2)*$U11 + $U11+1)), "") -> 292349 | Q11: =IFERROR(AVERAGE(INDEX(ipopt_output!Q:Q, (ROW()-2)*$U11+2):INDEX(ipopt_output!Q:Q, (ROW()-2)*$U11 + $U11+1)), "") -> 3560 | R11: =IFERROR(AVERAGE(INDEX(ipopt_output!R:R, (ROW()-2)*$U11+2):INDEX(ipopt_output!R:R, (ROW()-2)*$U11 + $U11+1)), "") -> 470.21875 | S11: =IFERROR(AVERAGE(INDEX(ipopt_output!S:S, (ROW()-2)*$U11+2):INDEX(ipopt_output!S:S, (ROW()-2)*$U11 + $U11+1)), "") -> 20260407 | T11: =IFERROR(AVERAGE(INDEX(ipopt_output!T:T, (ROW()-2)*$U11+2):INDEX(ipopt_output!T:T, (ROW()-2)*$U11 + $U11+1)), "") -> 161448.75 | U11: {=COUNTIF(ipopt_output!A:A,INDEX(ipopt_output!A:A,SUM(U$2:U10)+2))} -> 4
A12: {=INDEX(ipopt_output!A:A, (ROW()-2)*$U12+2)} -> spot_jump_twist_rk4_py | B12: {=INDEX(ipopt_output!B:B, (ROW()-2)*$U12+2)} -> Optimal Solution Found. | C12: =IFERROR(AVERAGE(INDEX(ipopt_output!C:C, (ROW()-2)*$U12+2):INDEX(ipopt_output!C:C, (ROW()-2)*$U12 + $U12+1)), "") -> 3400 | D12: =IFERROR(AVERAGE(INDEX(ipopt_output!D:D, (ROW()-2)*$U12+2):INDEX(ipopt_output!D:D, (ROW()-2)*$U12 + $U12+1)), "") -> 2787 | E12: =IFERROR(AVERAGE(INDEX(ipopt_output!E:E, (ROW()-2)*$U12+2):INDEX(ipopt_output!E:E, (ROW()-2)*$U12 + $U12+1)), "") -> 1180 | F12: =IFERROR(AVERAGE(INDEX(ipopt_output!F:F, (ROW()-2)*$U12+2):INDEX(ipopt_output!F:F, (ROW()-2)*$U12 + $U12+1)), "") -> 330 | G12: =IFERROR(AVERAGE(INDEX(ipopt_output!G:G, (ROW()-2)*$U12+2):INDEX(ipopt_output!G:G, (ROW()-2)*$U12 + $U12+1)), "") -> 13127.375 | H12: =IFERROR(AVERAGE(INDEX(ipopt_output!H:H, (ROW()-2)*$U12+2):INDEX(ipopt_output!H:H, (ROW()-2)*$U12 + $U12+1)), "") -> 1.4127164e-07 | I12: =IFERROR(AVERAGE(INDEX(ipopt_output!I:I, (ROW()-2)*$U12+2):INDEX(ipopt_output!I:I, (ROW()-2)*$U12 + $U12+1)), "") -> 41.1305 | J12: =IFERROR(AVERAGE(INDEX(ipopt_output!J:J, (ROW()-2)*$U12+2):INDEX(ipopt_output!J:J, (ROW()-2)*$U12 + $U12+1)), "") -> 11.43875 | K12: =IFERROR(AVERAGE(INDEX(ipopt_output!K:K, (ROW()-2)*$U12+2):INDEX(ipopt_output!K:K, (ROW()-2)*$U12 + $U12+1)), "") -> 66.521995 | L12: =IFERROR(AVERAGE(INDEX(ipopt_output!L:L, (ROW()-2)*$U12+2):INDEX(ipopt_output!L:L, (ROW()-2)*$U12 + $U12+1)), "") | M12: =IFERROR(AVERAGE(INDEX(ipopt_output!M:M, (ROW()-2)*$U12+2):INDEX(ipopt_output!M:M, (ROW()-2)*$U12 + $U12+1)), "") | N12: =IFERROR(AVERAGE(INDEX(ipopt_output!N:N, (ROW()-2)*$U12+2):INDEX(ipopt_output!N:N, (ROW()-2)*$U12 + $U12+1)), "") | O12: =IFERROR(AVERAGE(INDEX(ipopt_output!O:O, (ROW()-2)*$U12+2):INDEX(ipopt_output!O:O, (ROW()-2)*$U12 + $U12+1)), "") | P12: =IFERROR(AVERAGE(INDEX(ipopt_output!P:P, (ROW()-2)*$U12+2):INDEX(ipopt_output!P:P, (ROW()-2)*$U12 + $U12+1)), "") | Q12: =IFERROR(AVERAGE(INDEX(ipopt_output!Q:Q, (ROW()-2)*$U12+2):INDEX(ipopt_output!Q:Q, (ROW()-2)*$U12 + $U12+1)), "") | R12: =IFERROR(AVERAGE(INDEX(ipopt_output!R:R, (ROW()-2)*$U12+2):INDEX(ipopt_output!R:R, (ROW()-2)*$U12 + $U12+1)), "") -> 66.521975 | S12: =IFERROR(AVERAGE(INDEX(ipopt_output!S:S, (ROW()-2)*$U12+2):INDEX(ipopt_output!S:S, (ROW()-2)*$U12 + $U12+1)), "") -> 20260407 | T12: =IFERROR(AVERAGE(INDEX(ipopt_output!T:T, (ROW()-2)*$U12+2):INDEX(ipopt_output!T:T, (ROW()-2)*$U12 + $U12+1)), "") -> 169857.75 | U12: {=COUNTIF(ipopt_output!A:A,INDEX(ipopt_output!A:A,SUM(U$2:U11)+2))} -> 4
A13: {=INDEX(ipopt_output!A:A, (ROW()-2)*$U13+2)} -> spot_jump_twist_rk4_run | B13: {=INDEX(ipopt_output!B:B, (ROW()-2)*$U13+2)} -> Optimal Solution Found. | C13: =IFERROR(AVERAGE(INDEX(ipopt_output!C:C, (ROW()-2)*$U13+2):INDEX(ipopt_output!C:C, (ROW()-2)*$U13 + $U13+1)), "") -> 12436 | D13: =IFERROR(AVERAGE(INDEX(ipopt_output!D:D, (ROW()-2)*$U13+2):INDEX(ipopt_output!D:D, (ROW()-2)*$U13 + $U13+1)), "") -> 11810 | E13: =IFERROR(AVERAGE(INDEX(ipopt_output!E:E, (ROW()-2)*$U13+2):INDEX(ipopt_output!E:E, (ROW()-2)*$U13 + $U13+1)), "") -> 1080 | F13: =IFERROR(AVERAGE(INDEX(ipopt_output!F:F, (ROW()-2)*$U13+2):INDEX(ipopt_output!F:F, (ROW()-2)*$U13 + $U13+1)), "") -> 189 | G13: =IFERROR(AVERAGE(INDEX(ipopt_output!G:G, (ROW()-2)*$U13+2):INDEX(ipopt_output!G:G, (ROW()-2)*$U13 + $U13+1)), "") -> 55595.282 | H13: =IFERROR(AVERAGE(INDEX(ipopt_output!H:H, (ROW()-2)*$U13+2):INDEX(ipopt_output!H:H, (ROW()-2)*$U13 + $U13+1)), "") -> 2.9638352e-05 | I13: =IFERROR(AVERAGE(INDEX(ipopt_output!I:I, (ROW()-2)*$U13+2):INDEX(ipopt_output!I:I, (ROW()-2)*$U13 + $U13+1)), "") -> 71.885 | J13: =IFERROR(AVERAGE(INDEX(ipopt_output!J:J, (ROW()-2)*$U13+2):INDEX(ipopt_output!J:J, (ROW()-2)*$U13 + $U13+1)), "") -> 556.813 | K13: =IFERROR(AVERAGE(INDEX(ipopt_output!K:K, (ROW()-2)*$U13+2):INDEX(ipopt_output!K:K, (ROW()-2)*$U13 + $U13+1)), "") | L13: =IFERROR(AVERAGE(INDEX(ipopt_output!L:L, (ROW()-2)*$U13+2):INDEX(ipopt_output!L:L, (ROW()-2)*$U13 + $U13+1)), "") -> 2.0014388 | M13: =IFERROR(AVERAGE(INDEX(ipopt_output!M:M, (ROW()-2)*$U13+2):INDEX(ipopt_output!M:M, (ROW()-2)*$U13 + $U13+1)), "") -> 632.87945 | N13: =IFERROR(AVERAGE(INDEX(ipopt_output!N:N, (ROW()-2)*$U13+2):INDEX(ipopt_output!N:N, (ROW()-2)*$U13 + $U13+1)), "") -> 309215 | O13: =IFERROR(AVERAGE(INDEX(ipopt_output!O:O, (ROW()-2)*$U13+2):INDEX(ipopt_output!O:O, (ROW()-2)*$U13 + $U13+1)), "") -> 12436 | P13: =IFERROR(AVERAGE(INDEX(ipopt_output!P:P, (ROW()-2)*$U13+2):INDEX(ipopt_output!P:P, (ROW()-2)*$U13 + $U13+1)), "") -> 318599 | Q13: =IFERROR(AVERAGE(INDEX(ipopt_output!Q:Q, (ROW()-2)*$U13+2):INDEX(ipopt_output!Q:Q, (ROW()-2)*$U13 + $U13+1)), "") -> 12890 | R13: =IFERROR(AVERAGE(INDEX(ipopt_output!R:R, (ROW()-2)*$U13+2):INDEX(ipopt_output!R:R, (ROW()-2)*$U13 + $U13+1)), "") -> 634.88075 | S13: =IFERROR(AVERAGE(INDEX(ipopt_output!S:S, (ROW()-2)*$U13+2):INDEX(ipopt_output!S:S, (ROW()-2)*$U13 + $U13+1)), "") -> 20260407 | T13: =IFERROR(AVERAGE(INDEX(ipopt_output!T:T, (ROW()-2)*$U13+2):INDEX(ipopt_output!T:T, (ROW()-2)*$U13 + $U13+1)), "") -> 161448.75 | U13: {=COUNTIF(ipopt_output!A:A,INDEX(ipopt_output!A:A,SUM(U$2:U12)+2))} -> 4

Sheet std. dev
A1: =ipopt_output!A1 -> run | B1: =ipopt_output!B1 -> status | C1: =ipopt_output!C1 -> variables | D1: =ipopt_output!D1 -> equality_constraints | E1: =ipopt_output!E1 -> inequality_constraints | F1: =ipopt_output!F1 -> iterations | G1: =ipopt_output!G1 -> objective_unscaled | H1: =ipopt_output!H1 -> constraint_violation_unscaled | ... T1: =ipopt_output!T1 -> run_start_time
A2: {=INDEX(ipopt_output!A:A, (ROW()-2)*averages!$U2+2)} -> cart_pole_swing_col3_py | B2: {=INDEX(ipopt_output!B:B, (ROW()-2)*averages!$U2+2)} -> Optimal Solution Found. | C2: =IFERROR(_xlfn.STDEV.S(INDEX(ipopt_output!C:C, (ROW()-2)*averages!$U2+2):INDEX(ipopt_output!C:C, (ROW()-2)*averages!$U2+averages!$U2+1)), "") -> 0 | D2: =IFERROR(_xlfn.STDEV.S(INDEX(ipopt_output!D:D, (ROW()-2)*averages!$U2+2):INDEX(ipopt_output!D:D, (ROW()-2)*averages!$U2+averages!$U2+1)), "") -> 0 | E2: =IFERROR(_xlfn.STDEV.S(INDEX(ipopt_output!E:E, (ROW()-2)*averages!$U2+2):INDEX(ipopt_output!E:E, (ROW()-2)*averages!$U2+averages!$U2+1)), "") -> 0 | F2: =IFERROR(_xlfn.STDEV.S(INDEX(ipopt_output!F:F, (ROW()-2)*averages!$U2+2):INDEX(ipopt_output!F:F, (ROW()-2)*averages!$U2+averages!$U2+1)), "") -> 0 | G2: =IFERROR(_xlfn.STDEV.S(INDEX(ipopt_output!G:G, (ROW()-2)*averages!$U2+2):INDEX(ipopt_output!G:G, (ROW()-2)*averages!$U2+averages!$U2+1)), "") -> 0 | H2: =IFERROR(_xlfn.STDEV.S(INDEX(ipopt_output!H:H, (ROW()-2)*averages!$U2+2):INDEX(ipopt_output!H:H, (ROW()-2)*averages!$U2+averages!$U2+1)), "") -> 0 | I2: =IFERROR(_xlfn.STDEV.S(INDEX(ipopt_output!I:I, (ROW()-2)*averages!$U2+2):INDEX(ipopt_output!I:I, (ROW()-2)*averages!$U2+averages!$U2+1)), "") -> 0.019270011 | J2: =IFERROR(_xlfn.STDEV.S(INDEX(ipopt_output!J:J, (ROW()-2)*averages!$U2+2):INDEX(ipopt_output!J:J, (ROW()-2)*averages!$U2+averages!$U2+1)), "") -> 0.0026299556 | K2: =IFERROR(_xlfn.STDEV.S(INDEX(ipopt_output!K:K, (ROW()-2)*averages!$U2+2):INDEX(ipopt_output!K:K, (ROW()-2)*averages!$U2+averages!$U2+1)), "") -> 0.06527707 | L2: =IFERROR(_xlfn.STDEV.S(INDEX(ipopt_output!L:L, (ROW()-2)*averages!$U2+2):INDEX(ipopt_output!L:L, (ROW()-2)*averages!$U2+averages!$U2+1)), "") | M2: =IFERROR(_xlfn.STDEV.S(INDEX(ipopt_output!M:M, (ROW()-2)*averages!$U2+2):INDEX(ipopt_output!M:M, (ROW()-2)*averages!$U2+averages!$U2+1)), "") | N2: =IFERROR(_xlfn.STDEV.S(INDEX(ipopt_output!N:N, (ROW()-2)*averages!$U2+2):INDEX(ipopt_output!N:N, (ROW()-2)*averages!$U2+averages!$U2+1)), "") | O2: =IFERROR(_xlfn.STDEV.S(INDEX(ipopt_output!O:O, (ROW()-2)*averages!$U2+2):INDEX(ipopt_output!O:O, (ROW()-2)*averages!$U2+averages!$U2+1)), "") | P2: =IFERROR(_xlfn.STDEV.S(INDEX(ipopt_output!P:P, (ROW()-2)*averages!$U2+2):INDEX(ipopt_output!P:P, (ROW()-2)*averages!$U2+averages!$U2+1)), "") | Q2: =IFERROR(_xlfn.STDEV.S(INDEX(ipopt_output!Q:Q, (ROW()-2)*averages!$U2+2):INDEX(ipopt_output!Q:Q, (ROW()-2)*averages!$U2+averages!$U2+1)), "") | R2: =IFERROR(_xlfn.STDEV.S(INDEX(ipopt_output!R:R, (ROW()-2)*averages!$U2+2):INDEX(ipopt_output!R:R, (ROW()-2)*averages!$U2+averages!$U2+1)), "") -> 0.065278179 | S2: =IFERROR(_xlfn.STDEV.S(INDEX(ipopt_output!S:S, (ROW()-2)*averages!$U2+2):INDEX(ipopt_output!S:S, (ROW()-2)*averages!$U2+averages!$U2+1)), "") -> 0 | T2: =IFERROR(_xlfn.STDEV.S(INDEX(ipopt_output!T:T, (ROW()-2)*averages!$U2+2):INDEX(ipopt_output!T:T, (ROW()-2)*averages!$U2+averages!$U2+1)), "") -> 13847.342
A3: {=INDEX(ipopt_output!A:A, (ROW()-2)*averages!$U3+2)} -> cart_pole_swing_col3_run | B3: {=INDEX(ipopt_output!B:B, (ROW()-2)*averages!$U3+2)} -> Optimal Solution Found. | C3: =IFERROR(_xlfn.STDEV.S(INDEX(ipopt_output!C:C, (ROW()-2)*averages!$U3+2):INDEX(ipopt_output!C:C, (ROW()-2)*averages!$U3+averages!$U3+1)), "") -> 0 | D3: =IFERROR(_xlfn.STDEV.S(INDEX(ipopt_output!D:D, (ROW()-2)*averages!$U3+2):INDEX(ipopt_output!D:D, (ROW()-2)*averages!$U3+averages!$U3+1)), "") -> 0 | E3: =IFERROR(_xlfn.STDEV.S(INDEX(ipopt_output!E:E, (ROW()-2)*averages!$U3+2):INDEX(ipopt_output!E:E, (ROW()-2)*averages!$U3+averages!$U3+1)), "") -> 0 | F3: =IFERROR(_xlfn.STDEV.S(INDEX(ipopt_output!F:F, (ROW()-2)*averages!$U3+2):INDEX(ipopt_output!F:F, (ROW()-2)*averages!$U3+averages!$U3+1)), "") -> 0 | G3: =IFERROR(_xlfn.STDEV.S(INDEX(ipopt_output!G:G, (ROW()-2)*averages!$U3+2):INDEX(ipopt_output!G:G, (ROW()-2)*averages!$U3+averages!$U3+1)), "") -> 0 | H3: =IFERROR(_xlfn.STDEV.S(INDEX(ipopt_output!H:H, (ROW()-2)*averages!$U3+2):INDEX(ipopt_output!H:H, (ROW()-2)*averages!$U3+averages!$U3+1)), "") -> 0 | I3: =IFERROR(_xlfn.STDEV.S(INDEX(ipopt_output!I:I, (ROW()-2)*averages!$U3+2):INDEX(ipopt_output!I:I, (ROW()-2)*averages!$U3+averages!$U3+1)), "") -> 0.062553977 | J3: =IFERROR(_xlfn.STDEV.S(INDEX(ipopt_output!J:J, (ROW()-2)*averages!$U3+2):INDEX(ipopt_output!J:J, (ROW()-2)*averages!$U3+averages!$U3+1)), "") -> 0.013662601 | K3: =IFERROR(_xlfn.STDEV.S(INDEX(ipopt_output!K:K, (ROW()-2)*averages!$U3+2):INDEX(ipopt_output!K:K, (ROW()-2)*averages!$U3+averages!$U3+1)), "") | L3: =IFERROR(_xlfn.STDEV.S(INDEX(ipopt_output!L:L, (ROW()-2)*averages!$U3+2):INDEX(ipopt_output!L:L, (ROW()-2)*averages!$U3+averages!$U3+1)), "") -> 0.0037252987 | M3: =IFERROR(_xlfn.STDEV.S(INDEX(ipopt_output!M:M, (ROW()-2)*averages!$U3+2):INDEX(ipopt_output!M:M, (ROW()-2)*averages!$U3+averages!$U3+1)), "") -> 0.077719329 | N3: =IFERROR(_xlfn.STDEV.S(INDEX(ipopt_output!N:N, (ROW()-2)*averages!$U3+2):INDEX(ipopt_output!N:N, (ROW()-2)*averages!$U3+averages!$U3+1)), "") -> 0 | O3: =IFERROR(_xlfn.STDEV.S(INDEX(ipopt_output!O:O, (ROW()-2)*averages!$U3+2):INDEX(ipopt_output!O:O, (ROW()-2)*averages!$U3+averages!$U3+1)), "") -> 0 | P3: =IFERROR(_xlfn.STDEV.S(INDEX(ipopt_output!P:P, (ROW()-2)*averages!$U3+2):INDEX(ipopt_output!P:P, (ROW()-2)*averages!$U3+averages!$U3+1)), "") -> 0 | Q3: =IFERROR(_xlfn.STDEV.S(INDEX(ipopt_output!Q:Q, (ROW()-2)*averages!$U3+2):INDEX(ipopt_output!Q:Q, (ROW()-2)*averages!$U3+averages!$U3+1)), "") -> 0 | R3: =IFERROR(_xlfn.STDEV.S(INDEX(ipopt_output!R:R, (ROW()-2)*averages!$U3+2):INDEX(ipopt_output!R:R, (ROW()-2)*averages!$U3+averages!$U3+1)), "") -> 0.078273541 | S3: =IFERROR(_xlfn.STDEV.S(INDEX(ipopt_output!S:S, (ROW()-2)*averages!$U3+2):INDEX(ipopt_output!S:S, (ROW()-2)*averages!$U3+averages!$U3+1)), "") -> 0 | T3: =IFERROR(_xlfn.STDEV.S(INDEX(ipopt_output!T:T, (ROW()-2)*averages!$U3+2):INDEX(ipopt_output!T:T, (ROW()-2)*averages!$U3+averages!$U3+1)), "") -> 15420.055
A4: {=INDEX(ipopt_output!A:A, (ROW()-2)*averages!$U4+2)} -> cart_pole_swing_rk1_py | B4: {=INDEX(ipopt_output!B:B, (ROW()-2)*averages!$U4+2)} -> Optimal Solution Found. | C4: =IFERROR(_xlfn.STDEV.S(INDEX(ipopt_output!C:C, (ROW()-2)*averages!$U4+2):INDEX(ipopt_output!C:C, (ROW()-2)*averages!$U4+averages!$U4+1)), "") -> 0 | D4: =IFERROR(_xlfn.STDEV.S(INDEX(ipopt_output!D:D, (ROW()-2)*averages!$U4+2):INDEX(ipopt_output!D:D, (ROW()-2)*averages!$U4+averages!$U4+1)), "") -> 0 | E4: =IFERROR(_xlfn.STDEV.S(INDEX(ipopt_output!E:E, (ROW()-2)*averages!$U4+2):INDEX(ipopt_output!E:E, (ROW()-2)*averages!$U4+averages!$U4+1)), "") -> 0 | F4: =IFERROR(_xlfn.STDEV.S(INDEX(ipopt_output!F:F, (ROW()-2)*averages!$U4+2):INDEX(ipopt_output!F:F, (ROW()-2)*averages!$U4+averages!$U4+1)), "") -> 0 | G4: =IFERROR(_xlfn.STDEV.S(INDEX(ipopt_output!G:G, (ROW()-2)*averages!$U4+2):INDEX(ipopt_output!G:G, (ROW()-2)*averages!$U4+averages!$U4+1)), "") -> 0 | H4: =IFERROR(_xlfn.STDEV.S(INDEX(ipopt_output!H:H, (ROW()-2)*averages!$U4+2):INDEX(ipopt_output!H:H, (ROW()-2)*averages!$U4+averages!$U4+1)), "") -> 0 | I4: =IFERROR(_xlfn.STDEV.S(INDEX(ipopt_output!I:I, (ROW()-2)*averages!$U4+2):INDEX(ipopt_output!I:I, (ROW()-2)*averages!$U4+averages!$U4+1)), "") -> 0.023678401 | J4: =IFERROR(_xlfn.STDEV.S(INDEX(ipopt_output!J:J, (ROW()-2)*averages!$U4+2):INDEX(ipopt_output!J:J, (ROW()-2)*averages!$U4+averages!$U4+1)), "") -> 0.00391578 | K4: =IFERROR(_xlfn.STDEV.S(INDEX(ipopt_output!K:K, (ROW()-2)*averages!$U4+2):INDEX(ipopt_output!K:K, (ROW()-2)*averages!$U4+averages!$U4+1)), "") -> 0.022661026 | L4: =IFERROR(_xlfn.STDEV.S(INDEX(ipopt_output!L:L, (ROW()-2)*averages!$U4+2):INDEX(ipopt_output!L:L, (ROW()-2)*averages!$U4+averages!$U4+1)), "") | M4: =IFERROR(_xlfn.STDEV.S(INDEX(ipopt_output!M:M, (ROW()-2)*averages!$U4+2):INDEX(ipopt_output!M:M, (ROW()-2)*averages!$U4+averages!$U4+1)), "") | N4: =IFERROR(_xlfn.STDEV.S(INDEX(ipopt_output!N:N, (ROW()-2)*averages!$U4+2):INDEX(ipopt_output!N:N, (ROW()-2)*averages!$U4+averages!$U4+1)), "") | O4: =IFERROR(_xlfn.STDEV.S(INDEX(ipopt_output!O:O, (ROW()-2)*averages!$U4+2):INDEX(ipopt_output!O:O, (ROW()-2)*averages!$U4+averages!$U4+1)), "") | P4: =IFERROR(_xlfn.STDEV.S(INDEX(ipopt_output!P:P, (ROW()-2)*averages!$U4+2):INDEX(ipopt_output!P:P, (ROW()-2)*averages!$U4+averages!$U4+1)), "") | Q4: =IFERROR(_xlfn.STDEV.S(INDEX(ipopt_output!Q:Q, (ROW()-2)*averages!$U4+2):INDEX(ipopt_output!Q:Q, (ROW()-2)*averages!$U4+averages!$U4+1)), "") | R4: =IFERROR(_xlfn.STDEV.S(INDEX(ipopt_output!R:R, (ROW()-2)*averages!$U4+2):INDEX(ipopt_output!R:R, (ROW()-2)*averages!$U4+averages!$U4+1)), "") -> 0.022661092 | S4: =IFERROR(_xlfn.STDEV.S(INDEX(ipopt_output!S:S, (ROW()-2)*averages!$U4+2):INDEX(ipopt_output!S:S, (ROW()-2)*averages!$U4+averages!$U4+1)), "") -> 0 | T4: =IFERROR(_xlfn.STDEV.S(INDEX(ipopt_output!T:T, (ROW()-2)*averages!$U4+2):INDEX(ipopt_output!T:T, (ROW()-2)*averages!$U4+averages!$U4+1)), "") -> 13847.342
A5: {=INDEX(ipopt_output!A:A, (ROW()-2)*averages!$U5+2)} -> cart_pole_swing_rk1_run | B5: {=INDEX(ipopt_output!B:B, (ROW()-2)*averages!$U5+2)} -> Optimal Solution Found. | C5: =IFERROR(_xlfn.STDEV.S(INDEX(ipopt_output!C:C, (ROW()-2)*averages!$U5+2):INDEX(ipopt_output!C:C, (ROW()-2)*averages!$U5+averages!$U5+1)), "") -> 0 | D5: =IFERROR(_xlfn.STDEV.S(INDEX(ipopt_output!D:D, (ROW()-2)*averages!$U5+2):INDEX(ipopt_output!D:D, (ROW()-2)*averages!$U5+averages!$U5+1)), "") -> 0 | E5: =IFERROR(_xlfn.STDEV.S(INDEX(ipopt_output!E:E, (ROW()-2)*averages!$U5+2):INDEX(ipopt_output!E:E, (ROW()-2)*averages!$U5+averages!$U5+1)), "") -> 0 | F5: =IFERROR(_xlfn.STDEV.S(INDEX(ipopt_output!F:F, (ROW()-2)*averages!$U5+2):INDEX(ipopt_output!F:F, (ROW()-2)*averages!$U5+averages!$U5+1)), "") -> 0 | G5: =IFERROR(_xlfn.STDEV.S(INDEX(ipopt_output!G:G, (ROW()-2)*averages!$U5+2):INDEX(ipopt_output!G:G, (ROW()-2)*averages!$U5+averages!$U5+1)), "") -> 0 | H5: =IFERROR(_xlfn.STDEV.S(INDEX(ipopt_output!H:H, (ROW()-2)*averages!$U5+2):INDEX(ipopt_output!H:H, (ROW()-2)*averages!$U5+averages!$U5+1)), "") -> 0 | I5: =IFERROR(_xlfn.STDEV.S(INDEX(ipopt_output!I:I, (ROW()-2)*averages!$U5+2):INDEX(ipopt_output!I:I, (ROW()-2)*averages!$U5+averages!$U5+1)), "") -> 0.027317577 | J5: =IFERROR(_xlfn.STDEV.S(INDEX(ipopt_output!J:J, (ROW()-2)*averages!$U5+2):INDEX(ipopt_output!J:J, (ROW()-2)*averages!$U5+averages!$U5+1)), "") -> 0.010878113 | K5: =IFERROR(_xlfn.STDEV.S(INDEX(ipopt_output!K:K, (ROW()-2)*averages!$U5+2):INDEX(ipopt_output!K:K, (ROW()-2)*averages!$U5+averages!$U5+1)), "") | L5: =IFERROR(_xlfn.STDEV.S(INDEX(ipopt_output!L:L, (ROW()-2)*averages!$U5+2):INDEX(ipopt_output!L:L, (ROW()-2)*averages!$U5+averages!$U5+1)), "") -> 0.0037579601 | M5: =IFERROR(_xlfn.STDEV.S(INDEX(ipopt_output!M:M, (ROW()-2)*averages!$U5+2):INDEX(ipopt_output!M:M, (ROW()-2)*averages!$U5+averages!$U5+1)), "") -> 0.12734083 | N5: =IFERROR(_xlfn.STDEV.S(INDEX(ipopt_output!N:N, (ROW()-2)*averages!$U5+2):INDEX(ipopt_output!N:N, (ROW()-2)*averages!$U5+averages!$U5+1)), "") -> 0 | O5: =IFERROR(_xlfn.STDEV.S(INDEX(ipopt_output!O:O, (ROW()-2)*averages!$U5+2):INDEX(ipopt_output!O:O, (ROW()-2)*averages!$U5+averages!$U5+1)), "") -> 0 | P5: =IFERROR(_xlfn.STDEV.S(INDEX(ipopt_output!P:P, (ROW()-2)*averages!$U5+2):INDEX(ipopt_output!P:P, (ROW()-2)*averages!$U5+averages!$U5+1)), "") -> 0 | Q5: =IFERROR(_xlfn.STDEV.S(INDEX(ipopt_output!Q:Q, (ROW()-2)*averages!$U5+2):INDEX(ipopt_output!Q:Q, (ROW()-2)*averages!$U5+averages!$U5+1)), "") -> 0 | R5: =IFERROR(_xlfn.STDEV.S(INDEX(ipopt_output!R:R, (ROW()-2)*averages!$U5+2):INDEX(ipopt_output!R:R, (ROW()-2)*averages!$U5+averages!$U5+1)), "") -> 0.12876286 | S5: =IFERROR(_xlfn.STDEV.S(INDEX(ipopt_output!S:S, (ROW()-2)*averages!$U5+2):INDEX(ipopt_output!S:S, (ROW()-2)*averages!$U5+averages!$U5+1)), "") -> 0 | T5: =IFERROR(_xlfn.STDEV.S(INDEX(ipopt_output!T:T, (ROW()-2)*averages!$U5+2):INDEX(ipopt_output!T:T, (ROW()-2)*averages!$U5+averages!$U5+1)), "") -> 15420.055
A6: {=INDEX(ipopt_output!A:A, (ROW()-2)*averages!$U6+2)} -> cart_pole_swing_rk4_py | B6: {=INDEX(ipopt_output!B:B, (ROW()-2)*averages!$U6+2)} -> Optimal Solution Found. | C6: =IFERROR(_xlfn.STDEV.S(INDEX(ipopt_output!C:C, (ROW()-2)*averages!$U6+2):INDEX(ipopt_output!C:C, (ROW()-2)*averages!$U6+averages!$U6+1)), "") -> 0 | D6: =IFERROR(_xlfn.STDEV.S(INDEX(ipopt_output!D:D, (ROW()-2)*averages!$U6+2):INDEX(ipopt_output!D:D, (ROW()-2)*averages!$U6+averages!$U6+1)), "") -> 0 | E6: =IFERROR(_xlfn.STDEV.S(INDEX(ipopt_output!E:E, (ROW()-2)*averages!$U6+2):INDEX(ipopt_output!E:E, (ROW()-2)*averages!$U6+averages!$U6+1)), "") -> 0 | F6: =IFERROR(_xlfn.STDEV.S(INDEX(ipopt_output!F:F, (ROW()-2)*averages!$U6+2):INDEX(ipopt_output!F:F, (ROW()-2)*averages!$U6+averages!$U6+1)), "") -> 0 | G6: =IFERROR(_xlfn.STDEV.S(INDEX(ipopt_output!G:G, (ROW()-2)*averages!$U6+2):INDEX(ipopt_output!G:G, (ROW()-2)*averages!$U6+averages!$U6+1)), "") -> 0 | H6: =IFERROR(_xlfn.STDEV.S(INDEX(ipopt_output!H:H, (ROW()-2)*averages!$U6+2):INDEX(ipopt_output!H:H, (ROW()-2)*averages!$U6+averages!$U6+1)), "") -> 0 | I6: =IFERROR(_xlfn.STDEV.S(INDEX(ipopt_output!I:I, (ROW()-2)*averages!$U6+2):INDEX(ipopt_output!I:I, (ROW()-2)*averages!$U6+averages!$U6+1)), "") -> 0.0069522179 | J6: =IFERROR(_xlfn.STDEV.S(INDEX(ipopt_output!J:J, (ROW()-2)*averages!$U6+2):INDEX(ipopt_output!J:J, (ROW()-2)*averages!$U6+averages!$U6+1)), "") -> 0.0016329932 | K6: =IFERROR(_xlfn.STDEV.S(INDEX(ipopt_output!K:K, (ROW()-2)*averages!$U6+2):INDEX(ipopt_output!K:K, (ROW()-2)*averages!$U6+averages!$U6+1)), "") -> 0.057332092 | L6: =IFERROR(_xlfn.STDEV.S(INDEX(ipopt_output!L:L, (ROW()-2)*averages!$U6+2):INDEX(ipopt_output!L:L, (ROW()-2)*averages!$U6+averages!$U6+1)), "") | M6: =IFERROR(_xlfn.STDEV.S(INDEX(ipopt_output!M:M, (ROW()-2)*averages!$U6+2):INDEX(ipopt_output!M:M, (ROW()-2)*averages!$U6+averages!$U6+1)), "") | N6: =IFERROR(_xlfn.STDEV.S(INDEX(ipopt_output!N:N, (ROW()-2)*averages!$U6+2):INDEX(ipopt_output!N:N, (ROW()-2)*averages!$U6+averages!$U6+1)), "") | O6: =IFERROR(_xlfn.STDEV.S(INDEX(ipopt_output!O:O, (ROW()-2)*averages!$U6+2):INDEX(ipopt_output!O:O, (ROW()-2)*averages!$U6+averages!$U6+1)), "") | P6: =IFERROR(_xlfn.STDEV.S(INDEX(ipopt_output!P:P, (ROW()-2)*averages!$U6+2):INDEX(ipopt_output!P:P, (ROW()-2)*averages!$U6+averages!$U6+1)), "") | Q6: =IFERROR(_xlfn.STDEV.S(INDEX(ipopt_output!Q:Q, (ROW()-2)*averages!$U6+2):INDEX(ipopt_output!Q:Q, (ROW()-2)*averages!$U6+averages!$U6+1)), "") | R6: =IFERROR(_xlfn.STDEV.S(INDEX(ipopt_output!R:R, (ROW()-2)*averages!$U6+2):INDEX(ipopt_output!R:R, (ROW()-2)*averages!$U6+averages!$U6+1)), "") -> 0.057329562 | S6: =IFERROR(_xlfn.STDEV.S(INDEX(ipopt_output!S:S, (ROW()-2)*averages!$U6+2):INDEX(ipopt_output!S:S, (ROW()-2)*averages!$U6+averages!$U6+1)), "") -> 0 | T6: =IFERROR(_xlfn.STDEV.S(INDEX(ipopt_output!T:T, (ROW()-2)*averages!$U6+2):INDEX(ipopt_output!T:T, (ROW()-2)*averages!$U6+averages!$U6+1)), "") -> 13847.342
A7: {=INDEX(ipopt_output!A:A, (ROW()-2)*averages!$U7+2)} -> cart_pole_swing_rk4_run | B7: {=INDEX(ipopt_output!B:B, (ROW()-2)*averages!$U7+2)} -> Optimal Solution Found. | C7: =IFERROR(_xlfn.STDEV.S(INDEX(ipopt_output!C:C, (ROW()-2)*averages!$U7+2):INDEX(ipopt_output!C:C, (ROW()-2)*averages!$U7+averages!$U7+1)), "") -> 0 | D7: =IFERROR(_xlfn.STDEV.S(INDEX(ipopt_output!D:D, (ROW()-2)*averages!$U7+2):INDEX(ipopt_output!D:D, (ROW()-2)*averages!$U7+averages!$U7+1)), "") -> 0 | E7: =IFERROR(_xlfn.STDEV.S(INDEX(ipopt_output!E:E, (ROW()-2)*averages!$U7+2):INDEX(ipopt_output!E:E, (ROW()-2)*averages!$U7+averages!$U7+1)), "") -> 0 | F7: =IFERROR(_xlfn.STDEV.S(INDEX(ipopt_output!F:F, (ROW()-2)*averages!$U7+2):INDEX(ipopt_output!F:F, (ROW()-2)*averages!$U7+averages!$U7+1)), "") -> 0 | G7: =IFERROR(_xlfn.STDEV.S(INDEX(ipopt_output!G:G, (ROW()-2)*averages!$U7+2):INDEX(ipopt_output!G:G, (ROW()-2)*averages!$U7+averages!$U7+1)), "") -> 0 | H7: =IFERROR(_xlfn.STDEV.S(INDEX(ipopt_output!H:H, (ROW()-2)*averages!$U7+2):INDEX(ipopt_output!H:H, (ROW()-2)*averages!$U7+averages!$U7+1)), "") -> 0 | I7: =IFERROR(_xlfn.STDEV.S(INDEX(ipopt_output!I:I, (ROW()-2)*averages!$U7+2):INDEX(ipopt_output!I:I, (ROW()-2)*averages!$U7+averages!$U7+1)), "") -> 0.072403384 | J7: =IFERROR(_xlfn.STDEV.S(INDEX(ipopt_output!J:J, (ROW()-2)*averages!$U7+2):INDEX(ipopt_output!J:J, (ROW()-2)*averages!$U7+averages!$U7+1)), "") -> 0.017291616 | K7: =IFERROR(_xlfn.STDEV.S(INDEX(ipopt_output!K:K, (ROW()-2)*averages!$U7+2):INDEX(ipopt_output!K:K, (ROW()-2)*averages!$U7+averages!$U7+1)), "") | L7: =IFERROR(_xlfn.STDEV.S(INDEX(ipopt_output!L:L, (ROW()-2)*averages!$U7+2):INDEX(ipopt_output!L:L, (ROW()-2)*averages!$U7+averages!$U7+1)), "") -> 0.00093260973 | M7: =IFERROR(_xlfn.STDEV.S(INDEX(ipopt_output!M:M, (ROW()-2)*averages!$U7+2):INDEX(ipopt_output!M:M, (ROW()-2)*averages!$U7+averages!$U7+1)), "") -> 0.098834067 | N7: =IFERROR(_xlfn.STDEV.S(INDEX(ipopt_output!N:N, (ROW()-2)*averages!$U7+2):INDEX(ipopt_output!N:N, (ROW()-2)*averages!$U7+averages!$U7+1)), "") -> 0 | O7: =IFERROR(_xlfn.STDEV.S(INDEX(ipopt_output!O:O, (ROW()-2)*averages!$U7+2):INDEX(ipopt_output!O:O, (ROW()-2)*averages!$U7+averages!$U7+1)), "") -> 0 | P7: =IFERROR(_xlfn.STDEV.S(INDEX(ipopt_output!P:P, (ROW()-2)*averages!$U7+2):INDEX(ipopt_output!P:P, (ROW()-2)*averages!$U7+averages!$U7+1)), "") -> 0 | Q7: =IFERROR(_xlfn.STDEV.S(INDEX(ipopt_output!Q:Q, (ROW()-2)*averages!$U7+2):INDEX(ipopt_output!Q:Q, (ROW()-2)*averages!$U7+averages!$U7+1)), "") -> 0 | R7: =IFERROR(_xlfn.STDEV.S(INDEX(ipopt_output!R:R, (ROW()-2)*averages!$U7+2):INDEX(ipopt_output!R:R, (ROW()-2)*averages!$U7+averages!$U7+1)), "") -> 0.099253168 | S7: =IFERROR(_xlfn.STDEV.S(INDEX(ipopt_output!S:S, (ROW()-2)*averages!$U7+2):INDEX(ipopt_output!S:S, (ROW()-2)*averages!$U7+averages!$U7+1)), "") -> 0 | T7: =IFERROR(_xlfn.STDEV.S(INDEX(ipopt_output!T:T, (ROW()-2)*averages!$U7+2):INDEX(ipopt_output!T:T, (ROW()-2)*averages!$U7+averages!$U7+1)), "") -> 15420.055
A8: {=INDEX(ipopt_output!A:A, (ROW()-2)*averages!$U8+2)} -> spot_jump_twist_col3_py | B8: {=INDEX(ipopt_output!B:B, (ROW()-2)*averages!$U8+2)} -> Converged to a point of local infeasibility. Problem may be infeasible. | C8: =IFERROR(_xlfn.STDEV.S(INDEX(ipopt_output!C:C, (ROW()-2)*averages!$U8+2):INDEX(ipopt_output!C:C, (ROW()-2)*averages!$U8+averages!$U8+1)), "") -> 0 | D8: =IFERROR(_xlfn.STDEV.S(INDEX(ipopt_output!D:D, (ROW()-2)*averages!$U8+2):INDEX(ipopt_output!D:D, (ROW()-2)*averages!$U8+averages!$U8+1)), "") -> 0 | E8: =IFERROR(_xlfn.STDEV.S(INDEX(ipopt_output!E:E, (ROW()-2)*averages!$U8+2):INDEX(ipopt_output!E:E, (ROW()-2)*averages!$U8+averages!$U8+1)), "") -> 0 | F8: =IFERROR(_xlfn.STDEV.S(INDEX(ipopt_output!F:F, (ROW()-2)*averages!$U8+2):INDEX(ipopt_output!F:F, (ROW()-2)*averages!$U8+averages!$U8+1)), "") -> 0 | G8: =IFERROR(_xlfn.STDEV.S(INDEX(ipopt_output!G:G, (ROW()-2)*averages!$U8+2):INDEX(ipopt_output!G:G, (ROW()-2)*averages!$U8+averages!$U8+1)), "") -> 0 | H8: =IFERROR(_xlfn.STDEV.S(INDEX(ipopt_output!H:H, (ROW()-2)*averages!$U8+2):INDEX(ipopt_output!H:H, (ROW()-2)*averages!$U8+averages!$U8+1)), "") -> 0 | I8: =IFERROR(_xlfn.STDEV.S(INDEX(ipopt_output!I:I, (ROW()-2)*averages!$U8+2):INDEX(ipopt_output!I:I, (ROW()-2)*averages!$U8+averages!$U8+1)), "") -> 0.66271412 | J8: =IFERROR(_xlfn.STDEV.S(INDEX(ipopt_output!J:J, (ROW()-2)*averages!$U8+2):INDEX(ipopt_output!J:J, (ROW()-2)*averages!$U8+averages!$U8+1)), "") -> 0.21162762 | K8: =IFERROR(_xlfn.STDEV.S(INDEX(ipopt_output!K:K, (ROW()-2)*averages!$U8+2):INDEX(ipopt_output!K:K, (ROW()-2)*averages!$U8+averages!$U8+1)), "") -> 3.2688935 | L8: =IFERROR(_xlfn.STDEV.S(INDEX(ipopt_output!L:L, (ROW()-2)*averages!$U8+2):INDEX(ipopt_output!L:L, (ROW()-2)*averages!$U8+averages!$U8+1)), "") | M8: =IFERROR(_xlfn.STDEV.S(INDEX(ipopt_output!M:M, (ROW()-2)*averages!$U8+2):INDEX(ipopt_output!M:M, (ROW()-2)*averages!$U8+averages!$U8+1)), "") | N8: =IFERROR(_xlfn.STDEV.S(INDEX(ipopt_output!N:N, (ROW()-2)*averages!$U8+2):INDEX(ipopt_output!N:N, (ROW()-2)*averages!$U8+averages!$U8+1)), "") | O8: =IFERROR(_xlfn.STDEV.S(INDEX(ipopt_output!O:O, (ROW()-2)*averages!$U8+2):INDEX(ipopt_output!O:O, (ROW()-2)*averages!$U8+averages!$U8+1)), "") | P8: =IFERROR(_xlfn.STDEV.S(INDEX(ipopt_output!P:P, (ROW()-2)*averages!$U8+2):INDEX(ipopt_output!P:P, (ROW()-2)*averages!$U8+averages!$U8+1)), "") | Q8: =IFERROR(_xlfn.STDEV.S(INDEX(ipopt_output!Q:Q, (ROW()-2)*averages!$U8+2):INDEX(ipopt_output!Q:Q, (ROW()-2)*averages!$U8+averages!$U8+1)), "") | R8: =IFERROR(_xlfn.STDEV.S(INDEX(ipopt_output!R:R, (ROW()-2)*averages!$U8+2):INDEX(ipopt_output!R:R, (ROW()-2)*averages!$U8+averages!$U8+1)), "") -> 3.2688594 | S8: =IFERROR(_xlfn.STDEV.S(INDEX(ipopt_output!S:S, (ROW()-2)*averages!$U8+2):INDEX(ipopt_output!S:S, (ROW()-2)*averages!$U8+averages!$U8+1)), "") -> 0 | T8: =IFERROR(_xlfn.STDEV.S(INDEX(ipopt_output!T:T, (ROW()-2)*averages!$U8+2):INDEX(ipopt_output!T:T, (ROW()-2)*averages!$U8+averages!$U8+1)), "") -> 13847.342
A9: {=INDEX(ipopt_output!A:A, (ROW()-2)*averages!$U9+2)} -> spot_jump_twist_col3_run | B9: {=INDEX(ipopt_output!B:B, (ROW()-2)*averages!$U9+2)} -> Optimal Solution Found. | C9: =IFERROR(_xlfn.STDEV.S(INDEX(ipopt_output!C:C, (ROW()-2)*averages!$U9+2):INDEX(ipopt_output!C:C, (ROW()-2)*averages!$U9+averages!$U9+1)), "") -> 0 | D9: =IFERROR(_xlfn.STDEV.S(INDEX(ipopt_output!D:D, (ROW()-2)*averages!$U9+2):INDEX(ipopt_output!D:D, (ROW()-2)*averages!$U9+averages!$U9+1)), "") -> 0 | E9: =IFERROR(_xlfn.STDEV.S(INDEX(ipopt_output!E:E, (ROW()-2)*averages!$U9+2):INDEX(ipopt_output!E:E, (ROW()-2)*averages!$U9+averages!$U9+1)), "") -> 0 | F9: =IFERROR(_xlfn.STDEV.S(INDEX(ipopt_output!F:F, (ROW()-2)*averages!$U9+2):INDEX(ipopt_output!F:F, (ROW()-2)*averages!$U9+averages!$U9+1)), "") -> 0 | G9: =IFERROR(_xlfn.STDEV.S(INDEX(ipopt_output!G:G, (ROW()-2)*averages!$U9+2):INDEX(ipopt_output!G:G, (ROW()-2)*averages!$U9+averages!$U9+1)), "") -> 0 | H9: =IFERROR(_xlfn.STDEV.S(INDEX(ipopt_output!H:H, (ROW()-2)*averages!$U9+2):INDEX(ipopt_output!H:H, (ROW()-2)*averages!$U9+averages!$U9+1)), "") -> 0 | I9: =IFERROR(_xlfn.STDEV.S(INDEX(ipopt_output!I:I, (ROW()-2)*averages!$U9+2):INDEX(ipopt_output!I:I, (ROW()-2)*averages!$U9+averages!$U9+1)), "") -> 3.6439955 | J9: =IFERROR(_xlfn.STDEV.S(INDEX(ipopt_output!J:J, (ROW()-2)*averages!$U9+2):INDEX(ipopt_output!J:J, (ROW()-2)*averages!$U9+averages!$U9+1)), "") -> 8.6723016 | K9: =IFERROR(_xlfn.STDEV.S(INDEX(ipopt_output!K:K, (ROW()-2)*averages!$U9+2):INDEX(ipopt_output!K:K, (ROW()-2)*averages!$U9+averages!$U9+1)), "") | L9: =IFERROR(_xlfn.STDEV.S(INDEX(ipopt_output!L:L, (ROW()-2)*averages!$U9+2):INDEX(ipopt_output!L:L, (ROW()-2)*averages!$U9+averages!$U9+1)), "") -> 0.059523713 | M9: =IFERROR(_xlfn.STDEV.S(INDEX(ipopt_output!M:M, (ROW()-2)*averages!$U9+2):INDEX(ipopt_output!M:M, (ROW()-2)*averages!$U9+averages!$U9+1)), "") -> 17.316903 | N9: =IFERROR(_xlfn.STDEV.S(INDEX(ipopt_output!N:N, (ROW()-2)*averages!$U9+2):INDEX(ipopt_output!N:N, (ROW()-2)*averages!$U9+averages!$U9+1)), "") -> 0 | O9: =IFERROR(_xlfn.STDEV.S(INDEX(ipopt_output!O:O, (ROW()-2)*averages!$U9+2):INDEX(ipopt_output!O:O, (ROW()-2)*averages!$U9+averages!$U9+1)), "") -> 0 | P9: =IFERROR(_xlfn.STDEV.S(INDEX(ipopt_output!P:P, (ROW()-2)*averages!$U9+2):INDEX(ipopt_output!P:P, (ROW()-2)*averages!$U9+averages!$U9+1)), "") -> 0 | Q9: =IFERROR(_xlfn.STDEV.S(INDEX(ipopt_output!Q:Q, (ROW()-2)*averages!$U9+2):INDEX(ipopt_output!Q:Q, (ROW()-2)*averages!$U9+averages!$U9+1)), "") -> 0 | R9: =IFERROR(_xlfn.STDEV.S(INDEX(ipopt_output!R:R, (ROW()-2)*averages!$U9+2):INDEX(ipopt_output!R:R, (ROW()-2)*averages!$U9+averages!$U9+1)), "") -> 17.326368 | S9: =IFERROR(_xlfn.STDEV.S(INDEX(ipopt_output!S:S, (ROW()-2)*averages!$U9+2):INDEX(ipopt_output!S:S, (ROW()-2)*averages!$U9+averages!$U9+1)), "") -> 0 | T9: =IFERROR(_xlfn.STDEV.S(INDEX(ipopt_output!T:T, (ROW()-2)*averages!$U9+2):INDEX(ipopt_output!T:T, (ROW()-2)*averages!$U9+averages!$U9+1)), "") -> 15420.055
A10: {=INDEX(ipopt_output!A:A, (ROW()-2)*averages!$U10+2)} -> spot_jump_twist_rk1_py | B10: {=INDEX(ipopt_output!B:B, (ROW()-2)*averages!$U10+2)} -> Converged to a point of local infeasibility. Problem may be infeasible. | C10: =IFERROR(_xlfn.STDEV.S(INDEX(ipopt_output!C:C, (ROW()-2)*averages!$U10+2):INDEX(ipopt_output!C:C, (ROW()-2)*averages!$U10+averages!$U10+1)), "") -> 0 | D10: =IFERROR(_xlfn.STDEV.S(INDEX(ipopt_output!D:D, (ROW()-2)*averages!$U10+2):INDEX(ipopt_output!D:D, (ROW()-2)*averages!$U10+averages!$U10+1)), "") -> 0 | E10: =IFERROR(_xlfn.STDEV.S(INDEX(ipopt_output!E:E, (ROW()-2)*averages!$U10+2):INDEX(ipopt_output!E:E, (ROW()-2)*averages!$U10+averages!$U10+1)), "") -> 0 | F10: =IFERROR(_xlfn.STDEV.S(INDEX(ipopt_output!F:F, (ROW()-2)*averages!$U10+2):INDEX(ipopt_output!F:F, (ROW()-2)*averages!$U10+averages!$U10+1)), "") -> 0 | G10: =IFERROR(_xlfn.STDEV.S(INDEX(ipopt_output!G:G, (ROW()-2)*averages!$U10+2):INDEX(ipopt_output!G:G, (ROW()-2)*averages!$U10+averages!$U10+1)), "") -> 0 | H10: =IFERROR(_xlfn.STDEV.S(INDEX(ipopt_output!H:H, (ROW()-2)*averages!$U10+2):INDEX(ipopt_output!H:H, (ROW()-2)*averages!$U10+averages!$U10+1)), "") -> 0 | I10: =IFERROR(_xlfn.STDEV.S(INDEX(ipopt_output!I:I, (ROW()-2)*averages!$U10+2):INDEX(ipopt_output!I:I, (ROW()-2)*averages!$U10+averages!$U10+1)), "") -> 0.78483417 | J10: =IFERROR(_xlfn.STDEV.S(INDEX(ipopt_output!J:J, (ROW()-2)*averages!$U10+2):INDEX(ipopt_output!J:J, (ROW()-2)*averages!$U10+averages!$U10+1)), "") -> 0.14125243 | K10: =IFERROR(_xlfn.STDEV.S(INDEX(ipopt_output!K:K, (ROW()-2)*averages!$U10+2):INDEX(ipopt_output!K:K, (ROW()-2)*averages!$U10+averages!$U10+1)), "") -> 2.9984499 | L10: =IFERROR(_xlfn.STDEV.S(INDEX(ipopt_output!L:L, (ROW()-2)*averages!$U10+2):INDEX(ipopt_output!L:L, (ROW()-2)*averages!$U10+averages!$U10+1)), "") | M10: =IFERROR(_xlfn.STDEV.S(INDEX(ipopt_output!M:M, (ROW()-2)*averages!$U10+2):INDEX(ipopt_output!M:M, (ROW()-2)*averages!$U10+averages!$U10+1)), "") | N10: =IFERROR(_xlfn.STDEV.S(INDEX(ipopt_output!N:N, (ROW()-2)*averages!$U10+2):INDEX(ipopt_output!N:N, (ROW()-2)*averages!$U10+averages!$U10+1)), "") | O10: =IFERROR(_xlfn.STDEV.S(INDEX(ipopt_output!O:O, (ROW()-2)*averages!$U10+2):INDEX(ipopt_output!O:O, (ROW()-2)*averages!$U10+averages!$U10+1)), "") | P10: =IFERROR(_xlfn.STDEV.S(INDEX(ipopt_output!P:P, (ROW()-2)*averages!$U10+2):INDEX(ipopt_output!P:P, (ROW()-2)*averages!$U10+averages!$U10+1)), "") | Q10: =IFERROR(_xlfn.STDEV.S(INDEX(ipopt_output!Q:Q, (ROW()-2)*averages!$U10+2):INDEX(ipopt_output!Q:Q, (ROW()-2)*averages!$U10+averages!$U10+1)), "") | R10: =IFERROR(_xlfn.STDEV.S(INDEX(ipopt_output!R:R, (ROW()-2)*averages!$U10+2):INDEX(ipopt_output!R:R, (ROW()-2)*averages!$U10+averages!$U10+1)), "") -> 2.9982917 | S10: =IFERROR(_xlfn.STDEV.S(INDEX(ipopt_output!S:S, (ROW()-2)*averages!$U10+2):INDEX(ipopt_output!S:S, (ROW()-2)*averages!$U10+averages!$U10+1)), "") -> 0 | T10: =IFERROR(_xlfn.STDEV.S(INDEX(ipopt_output!T:T, (ROW()-2)*averages!$U10+2):INDEX(ipopt_output!T:T, (ROW()-2)*averages!$U10+averages!$U10+1)), "") -> 13847.342
