Workbook
Name CSVPath: csv!$A$2

Sheet ipopt_output

Sheet averages
A1: =ipopt_output!A1 -> Column1 | B1: =ipopt_output!B1 -> Column2 | C1: =ipopt_output!C1 -> Column3 | D1: =ipopt_output!D1 -> Column4 | E1: =ipopt_output!E1 -> Column5 | F1: =ipopt_output!F1 -> Column6 | G1: =ipopt_output!G1 -> Column7 | H1: =ipopt_output!H1 -> Column8 | ... T1: =ipopt_output!T1 -> Column20 | U1: num_runs
A2: {=INDEX(ipopt_output!A:A, (ROW()-2)*$U2+2)} -> 0 | B2: {=INDEX(ipopt_output!B:B, (ROW()-2)*$U2+2)} -> 0 | C2: =IFERROR(AVERAGE(INDEX(ipopt_output!C:C, (ROW()-2)*$U2+2):INDEX(ipopt_output!C:C, (ROW()-2)*$U2 + $U2+1)), "") | D2: =IFERROR(AVERAGE(INDEX(ipopt_output!D:D, (ROW()-2)*$U2+2):INDEX(ipopt_output!D:D, (ROW()-2)*$U2 + $U2+1)), "") | E2: =IFERROR(AVERAGE(INDEX(ipopt_output!E:E, (ROW()-2)*$U2+2):INDEX(ipopt_output!E:E, (ROW()-2)*$U2 + $U2+1)), "") | F2: =IFERROR(AVERAGE(INDEX(ipopt_output!F:F, (ROW()-2)*$U2+2):INDEX(ipopt_output!F:F, (ROW()-2)*$U2 + $U2+1)), "") | G2: =IFERROR(AVERAGE(INDEX(ipopt_output!G:G, (ROW()-2)*$U2+2):INDEX(ipopt_output!G:G, (ROW()-2)*$U2 + $U2+1)), "") | H2: =IFERROR(AVERAGE(INDEX(ipopt_output!H:H, (ROW()-2)*$U2+2):INDEX(ipopt_output!H:H, (ROW()-2)*$U2 + $U2+1)), "") | I2: =IFERROR(AVERAGE(INDEX(ipopt_output!I:I, (ROW()-2)*$U2+2):INDEX(ipopt_output!I:I, (ROW()-2)*$U2 + $U2+1)), "") | J2: =IFERROR(AVERAGE(INDEX(ipopt_output!J:J, (ROW()-2)*$U2+2):INDEX(ipopt_output!J:J, (ROW()-2)*$U2 + $U2+1)), "") | K2: =IFERROR(AVERAGE(INDEX(ipopt_output!K:K, (ROW()-2)*$U2+2):INDEX(ipopt_output!K:K, (ROW()-2)*$U2 + $U2+1)), "") | L2: =IFERROR(AVERAGE(INDEX(ipopt_output!L:L, (ROW()-2)*$U2+2):INDEX(ipopt_output!L:L, (ROW()-2)*$U2 + $U2+1)), "") | M2: =IFERROR(AVERAGE(INDEX(ipopt_output!M:M, (ROW()-2)*$U2+2):INDEX(ipopt_output!M:M, (ROW()-2)*$U2 + $U2+1)), "") | N2: =IFERROR(AVERAGE(INDEX(ipopt_output!N:N, (ROW()-2)*$U2+2):INDEX(ipopt_output!N:N, (ROW()-2)*$U2 + $U2+1)), "") | O2: =IFERROR(AVERAGE(INDEX(ipopt_output!O:O, (ROW()-2)*$U2+2):INDEX(ipopt_output!O:O, (ROW()-2)*$U2 + $U2+1)), "") | P2: =IFERROR(AVERAGE(INDEX(ipopt_output!P:P, (ROW()-2)*$U2+2):INDEX(ipopt_output!P:P, (ROW()-2)*$U2 + $U2+1)), "") | Q2: =IFERROR(AVERAGE(INDEX(ipopt_output!Q:Q, (ROW()-2)*$U2+2):INDEX(ipopt_output!Q:Q, (ROW()-2)*$U2 + $U2+1)), "") | R2: =IFERROR(AVERAGE(INDEX(ipopt_output!R:R, (ROW()-2)*$U2+2):INDEX(ipopt_output!R:R, (ROW()-2)*$U2 + $U2+1)), "") | S2: =IFERROR(AVERAGE(INDEX(ipopt_output!S:S, (ROW()-2)*$U2+2):INDEX(ipopt_output!S:S, (ROW()-2)*$U2 + $U2+1)), "") | T2: =IFERROR(AVERAGE(INDEX(ipopt_output!T:T, (ROW()-2)*$U2+2):INDEX(ipopt_output!T:T, (ROW()-2)*$U2 + $U2+1)), "") | U2: =COUNTIF(ipopt_output!A:A, ipopt_output!A2) -> 0
A3: {=INDEX(ipopt_output!A:A, (ROW()-2)*$U3+2)} -> 0 | B3: {=INDEX(ipopt_output!B:B, (ROW()-2)*$U3+2)} -> 0 | C3: =IFERROR(AVERAGE(INDEX(ipopt_output!C:C, (ROW()-2)*$U3+2):INDEX(ipopt_output!C:C, (ROW()-2)*$U3 + $U3+1)), "") | D3: =IFERROR(AVERAGE(INDEX(ipopt_output!D:D, (ROW()-2)*$U3+2):INDEX(ipopt_output!D:D, (ROW()-2)*$U3 + $U3+1)), "") | E3: =IFERROR(AVERAGE(INDEX(ipopt_output!E:E, (ROW()-2)*$U3+2):INDEX(ipopt_output!E:E, (ROW()-2)*$U3 + $U3+1)), "") | F3: =IFERROR(AVERAGE(INDEX(ipopt_output!F:F, (ROW()-2)*$U3+2):INDEX(ipopt_output!F:F, (ROW()-2)*$U3 + $U3+1)), "") | G3: =IFERROR(AVERAGE(INDEX(ipopt_output!G:G, (ROW()-2)*$U3+2):INDEX(ipopt_output!G:G, (ROW()-2)*$U3 + $U3+1)), "") | H3: =IFERROR(AVERAGE(INDEX(ipopt_output!H:H, (ROW()-2)*$U3+2):INDEX(ipopt_output!H:H, (ROW()-2)*$U3 + $U3+1)), "") | I3: =IFERROR(AVERAGE(INDEX(ipopt_output!I:I, (ROW()-2)*$U3+2):INDEX(ipopt_output!I:I, (ROW()-2)*$U3 + $U3+1)), "") | J3: =IFERROR(AVERAGE(INDEX(ipopt_output!J:J, (ROW()-2)*$U3+2):INDEX(ipopt_output!J:J, (ROW()-2)*$U3 + $U3+1)), "") | K3: =IFERROR(AVERAGE(INDEX(ipopt_output!K:K, (ROW()-2)*$U3+2):INDEX(ipopt_output!K:K, (ROW()-2)*$U3 + $U3+1)), "") | L3: =IFERROR(AVERAGE(INDEX(ipopt_output!L:L, (ROW()-2)*$U3+2):INDEX(ipopt_output!L:L, (ROW()-2)*$U3 + $U3+1)), "") | M3: =IFERROR(AVERAGE(INDEX(ipopt_output!M:M, (ROW()-2)*$U3+2):INDEX(ipopt_output!M:M, (ROW()-2)*$U3 + $U3+1)), "") | N3: =IFERROR(AVERAGE(INDEX(ipopt_output!N:N, (ROW()-2)*$U3+2):INDEX(ipopt_output!N:N, (ROW()-2)*$U3 + $U3+1)), "") | O3: =IFERROR(AVERAGE(INDEX(ipopt_output!O:O, (ROW()-2)*$U3+2):INDEX(ipopt_output!O:O, (ROW()-2)*$U3 + $U3+1)), "") | P3: =IFERROR(AVERAGE(INDEX(ipopt_output!P:P, (ROW()-2)*$U3+2):INDEX(ipopt_output!P:P, (ROW()-2)*$U3 + $U3+1)), "") | Q3: =IFERROR(AVERAGE(INDEX(ipopt_output!Q:Q, (ROW()-2)*$U3+2):INDEX(ipopt_output!Q:Q, (ROW()-2)*$U3 + $U3+1)), "") | R3: =IFERROR(AVERAGE(INDEX(ipopt_output!R:R, (ROW()-2)*$U3+2):INDEX(ipopt_output!R:R, (ROW()-2)*$U3 + $U3+1)), "") | S3: =IFERROR(AVERAGE(INDEX(ipopt_output!S:S, (ROW()-2)*$U3+2):INDEX(ipopt_output!S:S, (ROW()-2)*$U3 + $U3+1)), "") | T3: =IFERROR(AVERAGE(INDEX(ipopt_output!T:T, (ROW()-2)*$U3+2):INDEX(ipopt_output!T:T, (ROW()-2)*$U3 + $U3+1)), "") | U3: {=COUNTIF(ipopt_output!A:A,INDEX(ipopt_output!A:A,SUM(U$2:U2)+2))} -> 0
A4: {=INDEX(ipopt_output!A:A, (ROW()-2)*$U4+2)} -> 0 | B4: {=INDEX(ipopt_output!B:B, (ROW()-2)*$U4+2)} -> 0 | C4: =IFERROR(AVERAGE(INDEX(ipopt_output!C:C, (ROW()-2)*$U4+2):INDEX(ipopt_output!C:C, (ROW()-2)*$U4 + $U4+1)), "") | D4: =IFERROR(AVERAGE(INDEX(ipopt_output!D:D, (ROW()-2)*$U4+2):INDEX(ipopt_output!D:D, (ROW()-2)*$U4 + $U4+1)), "") | E4: =IFERROR(AVERAGE(INDEX(ipopt_output!E:E, (ROW()-2)*$U4+2):INDEX(ipopt_output!E:E, (ROW()-2)*$U4 + $U4+1)), "") | F4: =IFERROR(AVERAGE(INDEX(ipopt_output!F:F, (ROW()-2)*$U4+2):INDEX(ipopt_output!F:F, (ROW()-2)*$U4 + $U4+1)), "") | G4: =IFERROR(AVERAGE(INDEX(ipopt_output!G:G, (ROW()-2)*$U4+2):INDEX(ipopt_output!G:G, (ROW()-2)*$U4 + $U4+1)), "") | H4: =IFERROR(AVERAGE(INDEX(ipopt_output!H:H, (ROW()-2)*$U4+2):INDEX(ipopt_output!H:H, (ROW()-2)*$U4 + $U4+1)), "") | I4: =IFERROR(AVERAGE(INDEX(ipopt_output!I:I, (ROW()-2)*$U4+2):INDEX(ipopt_output!I:I, (ROW()-2)*$U4 + $U4+1)), "") | J4: =IFERROR(AVERAGE(INDEX(ipopt_output!J:J, (ROW()-2)*$U4+2):INDEX(ipopt_output!J:J, (ROW()-2)*$U4 + $U4+1)), "") | K4: =IFERROR(AVERAGE(INDEX(ipopt_output!K:K, (ROW()-2)*$U4+2):INDEX(ipopt_output!K:K, (ROW()-2)*$U4 + $U4+1)), "") | L4: =IFERROR(AVERAGE(INDEX(ipopt_output!L:L, (ROW()-2)*$U4+2):INDEX(ipopt_output!L:L, (ROW()-2)*$U4 + $U4+1)), "") | M4: =IFERROR(AVERAGE(INDEX(ipopt_output!M:M, (ROW()-2)*$U4+2):INDEX(ipopt_output!M:M, (ROW()-2)*$U4 + $U4+1)), "") | N4: =IFERROR(AVERAGE(INDEX(ipopt_output!N:N, (ROW()-2)*$U4+2):INDEX(ipopt_output!N:N, (ROW()-2)*$U4 + $U4+1)), "") | O4: =IFERROR(AVERAGE(INDEX(ipopt_output!O:O, (ROW()-2)*$U4+2):INDEX(ipopt_output!O:O, (ROW()-2)*$U4 + $U4+1)), "") | P4: =IFERROR(AVERAGE(INDEX(ipopt_output!P:P, (ROW()-2)*$U4+2):INDEX(ipopt_output!P:P, (ROW()-2)*$U4 + $U4+1)), "") | Q4: =IFERROR(AVERAGE(INDEX(ipopt_output!Q:Q, (ROW()-2)*$U4+2):INDEX(ipopt_output!Q:Q, (ROW()-2)*$U4 + $U4+1)), "") | R4: =IFERROR(AVERAGE(INDEX(ipopt_output!R:R, (ROW()-2)*$U4+2):INDEX(ipopt_output!R:R, (ROW()-2)*$U4 + $U4+1)), "") | S4: =IFERROR(AVERAGE(INDEX(ipopt_output!S:S, (ROW()-2)*$U4+2):INDEX(ipopt_output!S:S, (ROW()-2)*$U4 + $U4+1)), "") | T4: =IFERROR(AVERAGE(INDEX(ipopt_output!T:T, (ROW()-2)*$U4+2):INDEX(ipopt_output!T:T, (ROW()-2)*$U4 + $U4+1)), "") | U4: {=COUNTIF(ipopt_output!A:A,INDEX(ipopt_output!A:A,SUM(U$2:U3)+2))} -> 0
A5: {=INDEX(ipopt_output!A:A, (ROW()-2)*$U5+2)} -> 0 | B5: {=INDEX(ipopt_output!B:B, (ROW()-2)*$U5+2)} -> 0 | C5: =IFERROR(AVERAGE(INDEX(ipopt_output!C:C, (ROW()-2)*$U5+2):INDEX(ipopt_output!C:C, (ROW()-2)*$U5 + $U5+1)), "") | D5: =IFERROR(AVERAGE(INDEX(ipopt_output!D:D, (ROW()-2)*$U5+2):INDEX(ipopt_output!D:D, (ROW()-2)*$U5 + $U5+1)), "") | E5: =IFERROR(AVERAGE(INDEX(ipopt_output!E:E, (ROW()-2)*$U5+2):INDEX(ipopt_output!E:E, (ROW()-2)*$U5 + $U5+1)), "") | F5: =IFERROR(AVERAGE(INDEX(ipopt_output!F:F, (ROW()-2)*$U5+2):INDEX(ipopt_output!F:F, (ROW()-2)*$U5 + $U5+1)), "") | G5: =IFERROR(AVERAGE(INDEX(ipopt_output!G:G, (ROW()-2)*$U5+2):INDEX(ipopt_output!G:G, (ROW()-2)*$U5 + $U5+1)), "") | H5: =IFERROR(AVERAGE(INDEX(ipopt_output!H:H, (ROW()-2)*$U5+2):INDEX(ipopt_output!H:H, (ROW()-2)*$U5 + $U5+1)), "") | I5: =IFERROR(AVERAGE(INDEX(ipopt_output!I:I, (ROW()-2)*$U5+2):INDEX(ipopt_output!I:I, (ROW()-2)*$U5 + $U5+1)), "") | J5: =IFERROR(AVERAGE(INDEX(ipopt_output!J:J, (ROW()-2)*$U5+2):INDEX(ipopt_output!J:J, (ROW()-2)*$U5 + $U5+1)), "") | K5: =IFERROR(AVERAGE(INDEX(ipopt_output!K:K, (ROW()-2)*$U5+2):INDEX(ipopt_output!K:K, (ROW()-2)*$U5 + $U5+1)), "") | L5: =IFERROR(AVERAGE(INDEX(ipopt_output!L:L, (ROW()-2)*$U5+2):INDEX(ipopt_output!L:L, (ROW()-2)*$U5 + $U5+1)), "") | M5: =IFERROR(AVERAGE(INDEX(ipopt_output!M:M, (ROW()-2)*$U5+2):INDEX(ipopt_output!M:M, (ROW()-2)*$U5 + $U5+1)), "") | N5: =IFERROR(AVERAGE(INDEX(ipopt_output!N:N, (ROW()-2)*$U5+2):INDEX(ipopt_output!N:N, (ROW()-2)*$U5 + $U5+1)), "") | O5: =IFERROR(AVERAGE(INDEX(ipopt_output!O:O, (ROW()-2)*$U5+2):INDEX(ipopt_output!O:O, (ROW()-2)*$U5 + $U5+1)), "") | P5: =IFERROR(AVERAGE(INDEX(ipopt_output!P:P, (ROW()-2)*$U5+2):INDEX(ipopt_output!P:P, (ROW()-2)*$U5 + $U5+1)), "") | Q5: =IFERROR(AVERAGE(INDEX(ipopt_output!Q:Q, (ROW()-2)*$U5+2):INDEX(ipopt_output!Q:Q, (ROW()-2)*$U5 + $U5+1)), "") | R5: =IFERROR(AVERAGE(INDEX(ipopt_output!R:R, (ROW()-2)*$U5+2):INDEX(ipopt_output!R:R, (ROW()-2)*$U5 + $U5+1)), "") | S5: =IFERROR(AVERAGE(INDEX(ipopt_output!S:S, (ROW()-2)*$U5+2):INDEX(ipopt_output!S:S, (ROW()-2)*$U5 + $U5+1)), "") | T5: =IFERROR(AVERAGE(INDEX(ipopt_output!T:T, (ROW()-2)*$U5+2):INDEX(ipopt_output!T:T, (ROW()-2)*$U5 + $U5+1)), "") | U5: {=COUNTIF(ipopt_output!A:A,INDEX(ipopt_output!A:A,SUM(U$2:U4)+2))} -> 0
A6: {=INDEX(ipopt_output!A:A, (ROW()-2)*$U6+2)} -> 0 | B6: {=INDEX(ipopt_output!B:B, (ROW()-2)*$U6+2)} -> 0 | C6: =IFERROR(AVERAGE(INDEX(ipopt_output!C:C, (ROW()-2)*$U6+2):INDEX(ipopt_output!C:C, (ROW()-2)*$U6 + $U6+1)), "") | D6: =IFERROR(AVERAGE(INDEX(ipopt_output!D:D, (ROW()-2)*$U6+2):INDEX(ipopt_output!D:D, (ROW()-2)*$U6 + $U6+1)), "") | E6: =IFERROR(AVERAGE(INDEX(ipopt_output!E:E, (ROW()-2)*$U6+2):INDEX(ipopt_output!E:E, (ROW()-2)*$U6 + $U6+1)), "") | F6: =IFERROR(AVERAGE(INDEX(ipopt_output!F:F, (ROW()-2)*$U6+2):INDEX(ipopt_output!F:F, (ROW()-2)*$U6 + $U6+1)), "") | G6: =IFERROR(AVERAGE(INDEX(ipopt_output!G:G, (ROW()-2)*$U6+2):INDEX(ipopt_output!G:G, (ROW()-2)*$U6 + $U6+1)), "") | H6: =IFERROR(AVERAGE(INDEX(ipopt_output!H:H, (ROW()-2)*$U6+2):INDEX(ipopt_output!H:H, (ROW()-2)*$U6 + $U6+1)), "") | I6: =IFERROR(AVERAGE(INDEX(ipopt_output!I:I, (ROW()-2)*$U6+2):INDEX(ipopt_output!I:I, (ROW()-2)*$U6 + $U6+1)), "") | J6: =IFERROR(AVERAGE(INDEX(ipopt_output!J:J, (ROW()-2)*$U6+2):INDEX(ipopt_output!J:J, (ROW()-2)*$U6 + $U6+1)), "") | K6: =IFERROR(AVERAGE(INDEX(ipopt_output!K:K, (ROW()-2)*$U6+2):INDEX(ipopt_output!K:K, (ROW()-2)*$U6 + $U6+1)), "") | L6: =IFERROR(AVERAGE(INDEX(ipopt_output!L:L, (ROW()-2)*$U6+2):INDEX(ipopt_output!L:L, (ROW()-2)*$U6 + $U6+1)), "") | M6: =IFERROR(AVERAGE(INDEX(ipopt_output!M:M, (ROW()-2)*$U6+2):INDEX(ipopt_output!M:M, (ROW()-2)*$U6 + $U6+1)), "") | N6: =IFERROR(AVERAGE(INDEX(ipopt_output!N:N, (ROW()-2)*$U6+2):INDEX(ipopt_output!N:N, (ROW()-2)*$U6 + $U6+1)), "") | O6: =IFERROR(AVERAGE(INDEX(ipopt_output!O:O, (ROW()-2)*$U6+2):INDEX(ipopt_output!O:O, (ROW()-2)*$U6 + $U6+1)), "") | P6: =IFERROR(AVERAGE(INDEX(ipopt_output!P:P, (ROW()-2)*$U6+2):INDEX(ipopt_output!P:P, (ROW()-2)*$U6 + $U6+1)), "") | Q6: =IFERROR(AVERAGE(INDEX(ipopt_output!Q:Q, (ROW()-2)*$U6+2):INDEX(ipopt_output!Q:Q, (ROW()-2)*$U6 + $U6+1)), "") | R6: =IFERROR(AVERAGE(INDEX(ipopt_output!R:R, (ROW()-2)*$U6+2):INDEX(ipopt_output!R:R, (ROW()-2)*$U6 + $U6+1)), "") | S6: =IFERROR(AVERAGE(INDEX(ipopt_output!S:S, (ROW()-2)*$U6+2):INDEX(ipopt_output!S:S, (ROW()-2)*$U6 + $U6+1)), "") | T6: =IFERROR(AVERAGE(INDEX(ipopt_output!T:T, (ROW()-2)*$U6+2):INDEX(ipopt_output!T:T, (ROW()-2)*$U6 + $U6+1)), "") | U6: {=COUNTIF(ipopt_output!A:A,INDEX(ipopt_output!A:A,SUM(U$2:U5)+2))} -> 0
A7: {=INDEX(ipopt_output!A:A, (ROW()-2)*$U7+2)} -> 0 | B7: {=INDEX(ipopt_output!B:B, (ROW()-2)*$U7+2)} -> 0 | C7: =IFERROR(AVERAGE(INDEX(ipopt_output!C:C, (ROW()-2)*$U7+2):INDEX(ipopt_output!C:C, (ROW()-2)*$U7 + $U7+1)), "") | D7: =IFERROR(AVERAGE(INDEX(ipopt_output!D:D, (ROW()-2)*$U7+2):INDEX(ipopt_output!D:D, (ROW()-2)*$U7 + $U7+1)), "") | E7: =IFERROR(AVERAGE(INDEX(ipopt_output!E:E, (ROW()-2)*$U7+2):INDEX(ipopt_output!E:E, (ROW()-2)*$U7 + $U7+1)), "") | F7: =IFERROR(AVERAGE(INDEX(ipopt_output!F:F, (ROW()-2)*$U7+2):INDEX(ipopt_output!F:F, (ROW()-2)*$U7 + $U7+1)), "") | G7: =IFERROR(AVERAGE(INDEX(ipopt_output!G:G, (ROW()-2)*$U7+2):INDEX(ipopt_output!G:G, (ROW()-2)*$U7 + $U7+1)), "") | H7: =IFERROR(AVERAGE(INDEX(ipopt_output!H:H, (ROW()-2)*$U7+2):INDEX(ipopt_output!H:H, (ROW()-2)*$U7 + $U7+1)), "") | I7: =IFERROR(AVERAGE(INDEX(ipopt_output!I:I, (ROW()-2)*$U7+2):INDEX(ipopt_output!I:I, (ROW()-2)*$U7 + $U7+1)), "") | J7: =IFERROR(AVERAGE(INDEX(ipopt_output!J:J, (ROW()-2)*$U7+2):INDEX(ipopt_output!J:J, (ROW()-2)*$U7 + $U7+1)), "") | K7: =IFERROR(AVERAGE(INDEX(ipopt_output!K:K, (ROW()-2)*$U7+2):INDEX(ipopt_output!K:K, (ROW()-2)*$U7 + $U7+1)), "") | L7: =IFERROR(AVERAGE(INDEX(ipopt_output!L:L, (ROW()-2)*$U7+2):INDEX(ipopt_output!L:L, (ROW()-2)*$U7 + $U7+1)), "") | M7: =IFERROR(AVERAGE(INDEX(ipopt_output!M:M, (ROW()-2)*$U7+2):INDEX(ipopt_output!M:M, (ROW()-2)*$U7 + $U7+1)), "") | N7: =IFERROR(AVERAGE(INDEX(ipopt_output!N:N, (ROW()-2)*$U7+2):INDEX(ipopt_output!N:N, (ROW()-2)*$U7 + $U7+1)), "") | O7: =IFERROR(AVERAGE(INDEX(ipopt_output!O:O, (ROW()-2)*$U7+2):INDEX(ipopt_output!O:O, (ROW()-2)*$U7 + $U7+1)), "") | P7: =IFERROR(AVERAGE(INDEX(ipopt_output!P:P, (ROW()-2)*$U7+2):INDEX(ipopt_output!P:P, (ROW()-2)*$U7 + $U7+1)), "") | Q7: =IFERROR(AVERAGE(INDEX(ipopt_output!Q:Q, (ROW()-2)*$U7+2):INDEX(ipopt_output!Q:Q, (ROW()-2)*$U7 + $U7+1)), "") | R7: =IFERROR(AVERAGE(INDEX(ipopt_output!R:R, (ROW()-2)*$U7+2):INDEX(ipopt_output!R:R, (ROW()-2)*$U7 + $U7+1)), "") | S7: =IFERROR(AVERAGE(INDEX(ipopt_output!S:S, (ROW()-2)*$U7+2):INDEX(ipopt_output!S:S, (ROW()-2)*$U7 + $U7+1)), "") | T7: =IFERROR(AVERAGE(INDEX(ipopt_output!T:T, (ROW()-2)*$U7+2):INDEX(ipopt_output!T:T, (ROW()-2)*$U7 + $U7+1)), "") | U7: {=COUNTIF(ipopt_output!A:A,INDEX(ipopt_output!A:A,SUM(U$2:U6)+2))} -> 0
A8: {=INDEX(ipopt_output!A:A, (ROW()-2)*$U8+2)} -> 0 | B8: {=INDEX(ipopt_output!B:B, (ROW()-2)*$U8+2)} -> 0 | C8: =IFERROR(AVERAGE(INDEX(ipopt_output!C:C, (ROW()-2)*$U8+2):INDEX(ipopt_output!C:C, (ROW()-2)*$U8 + $U8+1)), "") | D8: =IFERROR(AVERAGE(INDEX(ipopt_output!D:D, (ROW()-2)*$U8+2):INDEX(ipopt_output!D:D, (ROW()-2)*$U8 + $U8+1)), "") | E8: =IFERROR(AVERAGE(INDEX(ipopt_output!E:E, (ROW()-2)*$U8+2):INDEX(ipopt_output!E:E, (ROW()-2)*$U8 + $U8+1)), "") | F8: =IFERROR(AVERAGE(INDEX(ipopt_output!F:F, (ROW()-2)*$U8+2):INDEX(ipopt_output!F:F, (ROW()-2)*$U8 + $U8+1)), "") | G8: =IFERROR(AVERAGE(INDEX(ipopt_output!G:G, (ROW()-2)*$U8+2):INDEX(ipopt_output!G:G, (ROW()-2)*$U8 + $U8+1)), "") | H8: =IFERROR(AVERAGE(INDEX(ipopt_output!H:H, (ROW()-2)*$U8+2):INDEX(ipopt_output!H:H, (ROW()-2)*$U8 + $U8+1)), "") | I8: =IFERROR(AVERAGE(INDEX(ipopt_output!I:I, (ROW()-2)*$U8+2):INDEX(ipopt_output!I:I, (ROW()-2)*$U8 + $U8+1)), "") | J8: =IFERROR(AVERAGE(INDEX(ipopt_output!J:J, (ROW()-2)*$U8+2):INDEX(ipopt_output!J:J, (ROW()-2)*$U8 + $U8+1)), "") | K8: =IFERROR(AVERAGE(INDEX(ipopt_output!K:K, (ROW()-2)*$U8+2):INDEX(ipopt_output!K:K, (ROW()-2)*$U8 + $U8+1)), "") | L8: =IFERROR(AVERAGE(INDEX(ipopt_output!L:L, (ROW()-2)*$U8+2):INDEX(ipopt_output!L:L, (ROW()-2)*$U8 + $U8+1)), "") | M8: =IFERROR(AVERAGE(INDEX(ipopt_output!M:M, (ROW()-2)*$U8+2):INDEX(ipopt_output!M:M, (ROW()-2)*$U8 + $U8+1)), "") | N8: =IFERROR(AVERAGE(INDEX(ipopt_output!N:N, (ROW()-2)*$U8+2):INDEX(ipopt_output!N:N, (ROW()-2)*$U8 + $U8+1)), "") | O8: =IFERROR(AVERAGE(INDEX(ipopt_output!O:O, (ROW()-2)*$U8+2):INDEX(ipopt_output!O:O, (ROW()-2)*$U8 + $U8+1)), "") | P8: =IFERROR(AVERAGE(INDEX(ipopt_output!P:P, (ROW()-2)*$U8+2):INDEX(ipopt_output!P:P, (ROW()-2)*$U8 + $U8+1)), "") | Q8: =IFERROR(AVERAGE(INDEX(ipopt_output!Q:Q, (ROW()-2)*$U8+2):INDEX(ipopt_output!Q:Q, (ROW()-2)*$U8 + $U8+1)), "") | R8: =IFERROR(AVERAGE(INDEX(ipopt_output!R:R, (ROW()-2)*$U8+2):INDEX(ipopt_output!R:R, (ROW()-2)*$U8 + $U8+1)), "") | S8: =IFERROR(AVERAGE(INDEX(ipopt_output!S:S, (ROW()-2)*$U8+2):INDEX(ipopt_output!S:S, (ROW()-2)*$U8 + $U8+1)), "") | T8: =IFERROR(AVERAGE(INDEX(ipopt_output!T:T, (ROW()-2)*$U8+2):INDEX(ipopt_output!T:T, (ROW()-2)*$U8 + $U8+1)), "") | U8: {=COUNTIF(ipopt_output!A:A,INDEX(ipopt_output!A:A,SUM(U$2:U7)+2))} -> 0
A9: {=INDEX(ipopt_output!A:A, (ROW()-2)*$U9+2)} -> 0 | B9: {=INDEX(ipopt_output!B:B, (ROW()-2)*$U9+2)} -> 0 | C9: =IFERROR(AVERAGE(INDEX(ipopt_output!C:C, (ROW()-2)*$U9+2):INDEX(ipopt_output!C:C, (ROW()-2)*$U9 + $U9+1)), "") | D9: =IFERROR(AVERAGE(INDEX(ipopt_output!D:D, (ROW()-2)*$U9+2):INDEX(ipopt_output!D:D, (ROW()-2)*$U9 + $U9+1)), "") | E9: =IFERROR(AVERAGE(INDEX(ipopt_output!E:E, (ROW()-2)*$U9+2):INDEX(ipopt_output!E:E, (ROW()-2)*$U9 + $U9+1)), "") | F9: =IFERROR(AVERAGE(INDEX(ipopt_output!F:F, (ROW()-2)*$U9+2):INDEX(ipopt_output!F:F, (ROW()-2)*$U9 + $U9+1)), "") | G9: =IFERROR(AVERAGE(INDEX(ipopt_output!G:G, (ROW()-2)*$U9+2):INDEX(ipopt_output!G:G, (ROW()-2)*$U9 + $U9+1)), "") | H9: =IFERROR(AVERAGE(INDEX(ipopt_output!H:H, (ROW()-2)*$U9+2):INDEX(ipopt_output!H:H, (ROW()-2)*$U9 + $U9+1)), "") | I9: =IFERROR(AVERAGE(INDEX(ipopt_output!I:I, (ROW()-2)*$U9+2):INDEX(ipopt_output!I:I, (ROW()-2)*$U9 + $U9+1)), "") | J9: =IFERROR(AVERAGE(INDEX(ipopt_output!J:J, (ROW()-2)*$U9+2):INDEX(ipopt_output!J:J, (ROW()-2)*$U9 + $U9+1)), "") | K9: =IFERROR(AVERAGE(INDEX(ipopt_output!K:K, (ROW()-2)*$U9+2):INDEX(ipopt_output!K:K, (ROW()-2)*$U9 + $U9+1)), "") | L9: =IFERROR(AVERAGE(INDEX(ipopt_output!L:L, (ROW()-2)*$U9+2):INDEX(ipopt_output!L:L, (ROW()-2)*$U9 + $U9+1)), "") | M9: =IFERROR(AVERAGE(INDEX(ipopt_output!M:M, (ROW()-2)*$U9+2):INDEX(ipopt_output!M:M, (ROW()-2)*$U9 + $U9+1)), "") | N9: =IFERROR(AVERAGE(INDEX(ipopt_output!N:N, (ROW()-2)*$U9+2):INDEX(ipopt_output!N:N, (ROW()-2)*$U9 + $U9+1)), "") | O9: =IFERROR(AVERAGE(INDEX(ipopt_output!O:O, (ROW()-2)*$U9+2):INDEX(ipopt_output!O:O, (ROW()-2)*$U9 + $U9+1)), "") | P9: =IFERROR(AVERAGE(INDEX(ipopt_output!P:P, (ROW()-2)*$U9+2):INDEX(ipopt_output!P:P, (ROW()-2)*$U9 + $U9+1)), "") | Q9: =IFERROR(AVERAGE(INDEX(ipopt_output!Q:Q, (ROW()-2)*$U9+2):INDEX(ipopt_output!Q:Q, (ROW()-2)*$U9 + $U9+1)), "") | R9: =IFERROR(AVERAGE(INDEX(ipopt_output!R:R, (ROW()-2)*$U9+2):INDEX(ipopt_output!R:R, (ROW()-2)*$U9 + $U9+1)), "") | S9: =IFERROR(AVERAGE(INDEX(ipopt_output!S:S, (ROW()-2)*$U9+2):INDEX(ipopt_output!S:S, (ROW()-2)*$U9 + $U9+1)), "") | T9: =IFERROR(AVERAGE(INDEX(ipopt_output!T:T, (ROW()-2)*$U9+2):INDEX(ipopt_output!T:T, (ROW()-2)*$U9 + $U9+1)), "") | U9: {=COUNTIF(ipopt_output!A:A,INDEX(ipopt_output!A:A,SUM(U$2:U8)+2))} -> 0
A10: {=INDEX(ipopt_output!A:A, (ROW()-2)*$U10+2)} -> 0 | B10: {=INDEX(ipopt_output!B:B, (ROW()-2)*$U10+2)} -> 0 | C10: =IFERROR(AVERAGE(INDEX(ipopt_output!C:C, (ROW()-2)*$U10+2):INDEX(ipopt_output!C:C, (ROW()-2)*$U10 + $U10+1)), "") | D10: =IFERROR(AVERAGE(INDEX(ipopt_output!D:D, (ROW()-2)*$U10+2):INDEX(ipopt_output!D:D, (ROW()-2)*$U10 + $U10+1)), "") | E10: =IFERROR(AVERAGE(INDEX(ipopt_output!E:E, (ROW()-2)*$U10+2):INDEX(ipopt_output!E:E, (ROW()-2)*$U10 + $U10+1)), "") | F10: =IFERROR(AVERAGE(INDEX(ipopt_output!F:F, (ROW()-2)*$U10+2):INDEX(ipopt_output!F:F, (ROW()-2)*$U10 + $U10+1)), "") | G10: =IFERROR(AVERAGE(INDEX(ipopt_output!G:G, (ROW()-2)*$U10+2):INDEX(ipopt_output!G:G, (ROW()-2)*$U10 + $U10+1)), "") | H10: =IFERROR(AVERAGE(INDEX(ipopt_output!H:H, (ROW()-2)*$U10+2):INDEX(ipopt_output!H:H, (ROW()-2)*$U10 + $U10+1)), "") | I10: =IFERROR(AVERAGE(INDEX(ipopt_output!I:I, (ROW()-2)*$U10+2):INDEX(ipopt_output!I:I, (ROW()-2)*$U10 + $U10+1)), "") | J10: =IFERROR(AVERAGE(INDEX(ipopt_output!J:J, (ROW()-2)*$U10+2):INDEX(ipopt_output!J:J, (ROW()-2)*$U10 + $U10+1)), "") | K10: =IFERROR(AVERAGE(INDEX(ipopt_output!K:K, (ROW()-2)*$U10+2):INDEX(ipopt_output!K:K, (ROW()-2)*$U10 + $U10+1)), "") | L10: =IFERROR(AVERAGE(INDEX(ipopt_output!L:L, (ROW()-2)*$U10+2):INDEX(ipopt_output!L:L, (ROW()-2)*$U10 + $U10+1)), "") | M10: =IFERROR(AVERAGE(INDEX(ipopt_output!M:M, (ROW()-2)*$U10+2):INDEX(ipopt_output!M:M, (ROW()-2)*$U10 + $U10+1)), "") | N10: =IFERROR(AVERAGE(INDEX(ipopt_output!N:N, (ROW()-2)*$U10+2):INDEX(ipopt_output!N:N, (ROW()-2)*$U10 + $U10+1)), "") | O10: =IFERROR(AVERAGE(INDEX(ipopt_output!O:O, (ROW()-2)*$U10+2):INDEX(ipopt_output!O:O, (ROW()-2)*$U10 + $U10+1)), "") | P10: =IFERROR(AVERAGE(INDEX(ipopt_output!P:P, (ROW()-2)*$U10+2):INDEX(ipopt_output!P:P, (ROW()-2)*$U10 + $U10+1)), "") | Q10: =IFERROR(AVERAGE(INDEX(ipopt_output!Q:Q, (ROW()-2)*$U10+2):INDEX(ipopt_output!Q:Q, (ROW()-2)*$U10 + $U10+1)), "") | R10: =IFERROR(AVERAGE(INDEX(ipopt_output!R:R, (ROW()-2)*$U10+2):INDEX(ipopt_output!R:R, (ROW()-2)*$U10 + $U10+1)), "") | S10: =IFERROR(AVERAGE(INDEX(ipopt_output!S:S, (ROW()-2)*$U10+2):INDEX(ipopt_output!S:S, (ROW()-2)*$U10 + $U10+1)), "") | T10: =IFERROR(AVERAGE(INDEX(ipopt_output!T:T, (ROW()-2)*$U10+2):INDEX(ipopt_output!T:T, (ROW()-2)*$U10 + $U10+1)), "") | U10: {=COUNTIF(ipopt_output!A:A,INDEX(ipopt_output!A:A,SUM(U$2:U9)+2))} -> 0
A11: {=INDEX(ipopt_output!A:A, (ROW()-2)*$U11+2)} -> 0 | B11: {=INDEX(ipopt_output!B:B, (ROW()-2)*$U11+2)} -> 0 | C11: =IFERROR(AVERAGE(INDEX(ipopt_output!C:C, (ROW()-2)*$U11+2):INDEX(ipopt_output!C:C, (ROW()-2)*$U11 + $U11+1)), "") | D11: =IFERROR(AVERAGE(INDEX(ipopt_output!D:D, (ROW()-2)*$U11+2):INDEX(ipopt_output!D:D, (ROW()-2)*$U11 + $U11+1)), "") | E11: =IFERROR(AVERAGE(INDEX(ipopt_output!E:E, (ROW()-2)*$U11+2):INDEX(ipopt_output!E:E, (ROW()-2)*$U11 + $U11+1)), "") | F11: =IFERROR(AVERAGE(INDEX(ipopt_output!F:F, (ROW()-2)*$U11+2):INDEX(ipopt_output!F:F, (ROW()-2)*$U11 + $U11+1)), "") | G11: =IFERROR(AVERAGE(INDEX(ipopt_output!G:G, (ROW()-2)*$U11+2):INDEX(ipopt_output!G:G, (ROW()-2)*$U11 + $U11+1)), "") | H11: =IFERROR(AVERAGE(INDEX(ipopt_output!H:H, (ROW()-2)*$U11+2):INDEX(ipopt_output!H:H, (ROW()-2)*$U11 + $U11+1)), "") | I11: =IFERROR(AVERAGE(INDEX(ipopt_output!I:I, (ROW()-2)*$U11+2):INDEX(ipopt_output!I:I, (ROW()-2)*$U11 + $U11+1)), "") | J11: =IFERROR(AVERAGE(INDEX(ipopt_output!J:J, (ROW()-2)*$U11+2):INDEX(ipopt_output!J:J, (ROW()-2)*$U11 + $U11+1)), "") | K11: =IFERROR(AVERAGE(INDEX(ipopt_output!K:K, (ROW()-2)*$U11+2):INDEX(ipopt_output!K:K, (ROW()-2)*$U11 + $U11+1)), "") | L11: =IFERROR(AVERAGE(INDEX(ipopt_output!L:L, (ROW()-2)*$U11+2):INDEX(ipopt_output!L:L, (ROW()-2)*$U11 + $U11+1)), "") | M11: =IFERROR(AVERAGE(INDEX(ipopt_output!M:M, (ROW()-2)*$U11+2):INDEX(ipopt_output!M:M, (ROW()-2)*$U11 + $U11+1)), "") | N11: =IFERROR(AVERAGE(INDEX(ipopt_output!N:N, (ROW()-2)*$U11+2):INDEX(ipopt_output!N:N, (ROW()-2)*$U11 + $U11+1)), "") | O11: =IFERROR(AVERAGE(INDEX(ipopt_output!O:O, (ROW()-2)*$U11+2):INDEX(ipopt_output!O:O, (ROW()-2)*$U11 + $U11+1)), "") | P11: =IFERROR(AVERAGE(INDEX(ipopt_output!P:P, (ROW()-2)*$U11+2):INDEX(ipopt_output!P:P, (ROW()-2)*$U11 + $U11+1)), "") | Q11: =IFERROR(AVERAGE(INDEX(ipopt_output!Q:Q, (ROW()-2)*$U11+2):INDEX(ipopt_output!Q:Q, (ROW()-2)*$U11 + $U11+1)), "") | R11: =IFERROR(AVERAGE(INDEX(ipopt_output!R:R, (ROW()-2)*$U11+2):INDEX(ipopt_output!R:R, (ROW()-2)*$U11 + $U11+1)), "") | S11: =IFERROR(AVERAGE(INDEX(ipopt_output!S:S, (ROW()-2)*$U11+2):INDEX(ipopt_output!S:S, (ROW()-2)*$U11 + $U11+1)), "") | T11: =IFERROR(AVERAGE(INDEX(ipopt_output!T:T, (ROW()-2)*$U11+2):INDEX(ipopt_output!T:T, (ROW()-2)*$U11 + $U11+1)), "") | U11: {=COUNTIF(ipopt_output!A:A,INDEX(ipopt_output!A:A,SUM(U$2:U10)+2))} -> 0
A12: {=INDEX(ipopt_output!A:A, (ROW()-2)*$U12+2)} -> 0 | B12: {=INDEX(ipopt_output!B:B, (ROW()-2)*$U12+2)} -> 0 | C12: =IFERROR(AVERAGE(INDEX(ipopt_output!C:C, (ROW()-2)*$U12+2):INDEX(ipopt_output!C:C, (ROW()-2)*$U12 + $U12+1)), "") | D12: =IFERROR(AVERAGE(INDEX(ipopt_output!D:D, (ROW()-2)*$U12+2):INDEX(ipopt_output!D:D, (ROW()-2)*$U12 + $U12+1)), "") | E12: =IFERROR(AVERAGE(INDEX(ipopt_output!E:E, (ROW()-2)*$U12+2):INDEX(ipopt_output!E:E, (ROW()-2)*$U12 + $U12+1)), "") | F12: =IFERROR(AVERAGE(INDEX(ipopt_output!F:F, (ROW()-2)*$U12+2):INDEX(ipopt_output!F:F, (ROW()-2)*$U12 + $U12+1)), "") | G12: =IFERROR(AVERAGE(INDEX(ipopt_output!G:G, (ROW()-2)*$U12+2):INDEX(ipopt_output!G:G, (ROW()-2)*$U12 + $U12+1)), "") | H12: =IFERROR(AVERAGE(INDEX(ipopt_output!H:H, (ROW()-2)*$U12+2):INDEX(ipopt_output!H:H, (ROW()-2)*$U12 + $U12+1)), "") | I12: =IFERROR(AVERAGE(INDEX(ipopt_output!I:I, (ROW()-2)*$U12+2):INDEX(ipopt_output!I:I, (ROW()-2)*$U12 + $U12+1)), "") | J12: =IFERROR(AVERAGE(INDEX(ipopt_output!J:J, (ROW()-2)*$U12+2):INDEX(ipopt_output!J:J, (ROW()-2)*$U12 + $U12+1)), "") | K12: =IFERROR(AVERAGE(INDEX(ipopt_output!K:K, (ROW()-2)*$U12+2):INDEX(ipopt_output!K:K, (ROW()-2)*$U12 + $U12+1)), "") | L12: =IFERROR(AVERAGE(INDEX(ipopt_output!L:L, (ROW()-2)*$U12+2):INDEX(ipopt_output!L:L, (ROW()-2)*$U12 + $U12+1)), "") | M12: =IFERROR(AVERAGE(INDEX(ipopt_output!M:M, (ROW()-2)*$U12+2):INDEX(ipopt_output!M:M, (ROW()-2)*$U12 + $U12+1)), "") | N12: =IFERROR(AVERAGE(INDEX(ipopt_output!N:N, (ROW()-2)*$U12+2):INDEX(ipopt_output!N:N, (ROW()-2)*$U12 + $U12+1)), "") | O12: =IFERROR(AVERAGE(INDEX(ipopt_output!O:O, (ROW()-2)*$U12+2):INDEX(ipopt_output!O:O, (ROW()-2)*$U12 + $U12+1)), "") | P12: =IFERROR(AVERAGE(INDEX(ipopt_output!P:P, (ROW()-2)*$U12+2):INDEX(ipopt_output!P:P, (ROW()-2)*$U12 + $U12+1)), "") | Q12: =IFERROR(AVERAGE(INDEX(ipopt_output!Q:Q, (ROW()-2)*$U12+2):INDEX(ipopt_output!Q:Q, (ROW()-2)*$U12 + $U12+1)), "") | R12: =IFERROR(AVERAGE(INDEX(ipopt_output!R:R, (ROW()-2)*$U12+2):INDEX(ipopt_output!R:R, (ROW()-2)*$U12 + $U12+1)), "") | S12: =IFERROR(AVERAGE(INDEX(ipopt_output!S:S, (ROW()-2)*$U12+2):INDEX(ipopt_output!S:S, (ROW()-2)*$U12 + $U12+1)), "") | T12: =IFERROR(AVERAGE(INDEX(ipopt_output!T:T, (ROW()-2)*$U12+2):INDEX(ipopt_output!T:T, (ROW()-2)*$U12 + $U12+1)), "") | U12: {=COUNTIF(ipopt_output!A:A,INDEX(ipopt_output!A:A,SUM(U$2:U11)+2))} -> 0
A13: {=INDEX(ipopt_output!A:A, (ROW()-2)*$U13+2)} -> 0 | B13: {=INDEX(ipopt_output!B:B, (ROW()-2)*$U13+2)} -> 0 | C13: =IFERROR(AVERAGE(INDEX(ipopt_output!C:C, (ROW()-2)*$U13+2):INDEX(ipopt_output!C:C, (ROW()-2)*$U13 + $U13+1)), "") | D13: =IFERROR(AVERAGE(INDEX(ipopt_output!D:D, (ROW()-2)*$U13+2):INDEX(ipopt_output!D:D, (ROW()-2)*$U13 + $U13+1)), "") | E13: =IFERROR(AVERAGE(INDEX(ipopt_output!E:E, (ROW()-2)*$U13+2):INDEX(ipopt_output!E:E, (ROW()-2)*$U13 + $U13+1)), "") | F13: =IFERROR(AVERAGE(INDEX(ipopt_output!F:F, (ROW()-2)*$U13+2):INDEX(ipopt_output!F:F, (ROW()-2)*$U13 + $U13+1)), "") | G13: =IFERROR(AVERAGE(INDEX(ipopt_output!G:G, (ROW()-2)*$U13+2):INDEX(ipopt_output!G:G, (ROW()-2)*$U13 + $U13+1)), "") | H13: =IFERROR(AVERAGE(INDEX(ipopt_output!H:H, (ROW()-2)*$U13+2):INDEX(ipopt_output!H:H, (ROW()-2)*$U13 + $U13+1)), "") | I13: =IFERROR(AVERAGE(INDEX(ipopt_output!I:I, (ROW()-2)*$U13+2):INDEX(ipopt_output!I:I, (ROW()-2)*$U13 + $U13+1)), "") | J13: =IFERROR(AVERAGE(INDEX(ipopt_output!J:J, (ROW()-2)*$U13+2):INDEX(ipopt_output!J:J, (ROW()-2)*$U13 + $U13+1)), "") | K13: =IFERROR(AVERAGE(INDEX(ipopt_output!K:K, (ROW()-2)*$U13+2):INDEX(ipopt_output!K:K, (ROW()-2)*$U13 + $U13+1)), "") | L13: =IFERROR(AVERAGE(INDEX(ipopt_output!L:L, (ROW()-2)*$U13+2):INDEX(ipopt_output!L:L, (ROW()-2)*$U13 + $U13+1)), "") | M13: =IFERROR(AVERAGE(INDEX(ipopt_output!M:M, (ROW()-2)*$U13+2):INDEX(ipopt_output!M:M, (ROW()-2)*$U13 + $U13+1)), "") | N13: =IFERROR(AVERAGE(INDEX(ipopt_output!N:N, (ROW()-2)*$U13+2):INDEX(ipopt_output!N:N, (ROW()-2)*$U13 + $U13+1)), "") | O13: =IFERROR(AVERAGE(INDEX(ipopt_output!O:O, (ROW()-2)*$U13+2):INDEX(ipopt_output!O:O, (ROW()-2)*$U13 + $U13+1)), "") | P13: =IFERROR(AVERAGE(INDEX(ipopt_output!P:P, (ROW()-2)*$U13+2):INDEX(ipopt_output!P:P, (ROW()-2)*$U13 + $U13+1)), "") | Q13: =IFERROR(AVERAGE(INDEX(ipopt_output!Q:Q, (ROW()-2)*$U13+2):INDEX(ipopt_output!Q:Q, (ROW()-2)*$U13 + $U13+1)), "") | R13: =IFERROR(AVERAGE(INDEX(ipopt_output!R:R, (ROW()-2)*$U13+2):INDEX(ipopt_output!R:R, (ROW()-2)*$U13 + $U13+1)), "") | S13: =IFERROR(AVERAGE(INDEX(ipopt_output!S:S, (ROW()-2)*$U13+2):INDEX(ipopt_output!S:S, (ROW()-2)*$U13 + $U13+1)), "") | T13: =IFERROR(AVERAGE(INDEX(ipopt_output!T:T, (ROW()-2)*$U13+2):INDEX(ipopt_output!T:T, (ROW()-2)*$U13 + $U13+1)), "") | U13: {=COUNTIF(ipopt_output!A:A,INDEX(ipopt_output!A:A,SUM(U$2:U12)+2))} -> 0

Sheet std. dev
A1: =ipopt_output!A1 -> Column1 | B1: =ipopt_output!B1 -> Column2 | C1: =ipopt_output!C1 -> Column3 | D1: =ipopt_output!D1 -> Column4 | E1: =ipopt_output!E1 -> Column5 | F1: =ipopt_output!F1 -> Column6 | G1: =ipopt_output!G1 -> Column7 | H1: =ipopt_output!H1 -> Column8 | ... T1: =ipopt_output!T1 -> Column20
A2: {=INDEX(ipopt_output!A:A, (ROW()-2)*averages!$U2+2)} -> 0 | B2: {=INDEX(ipopt_output!B:B, (ROW()-2)*averages!$U2+2)} -> 0 | C2: =IFERROR(_xlfn.STDEV.S(INDEX(ipopt_output!C:C, (ROW()-2)*averages!$U2+2):INDEX(ipopt_output!C:C, (ROW()-2)*averages!$U2+averages!$U2+1)), "") | D2: =IFERROR(_xlfn.STDEV.S(INDEX(ipopt_output!D:D, (ROW()-2)*averages!$U2+2):INDEX(ipopt_output!D:D, (ROW()-2)*averages!$U2+averages!$U2+1)), "") | E2: =IFERROR(_xlfn.STDEV.S(INDEX(ipopt_output!E:E, (ROW()-2)*averages!$U2+2):INDEX(ipopt_output!E:E, (ROW()-2)*averages!$U2+averages!$U2+1)), "") | F2: =IFERROR(_xlfn.STDEV.S(INDEX(ipopt_output!F:F, (ROW()-2)*averages!$U2+2):INDEX(ipopt_output!F:F, (ROW()-2)*averages!$U2+averages!$U2+1)), "") | G2: =IFERROR(_xlfn.STDEV.S(INDEX(ipopt_output!G:G, (ROW()-2)*averages!$U2+2):INDEX(ipopt_output!G:G, (ROW()-2)*averages!$U2+averages!$U2+1)), "") | H2: =IFERROR(_xlfn.STDEV.S(INDEX(ipopt_output!H:H, (ROW()-2)*averages!$U2+2):INDEX(ipopt_output!H:H, (ROW()-2)*averages!$U2+averages!$U2+1)), "") | I2: =IFERROR(_xlfn.STDEV.S(INDEX(ipopt_output!I:I, (ROW()-2)*averages!$U2+2):INDEX(ipopt_output!I:I, (ROW()-2)*averages!$U2+averages!$U2+1)), "") | J2: =IFERROR(_xlfn.STDEV.S(INDEX(ipopt_output!J:J, (ROW()-2)*averages!$U2+2):INDEX(ipopt_output!J:J, (ROW()-2)*averages!$U2+averages!$U2+1)), "") | K2: =IFERROR(_xlfn.STDEV.S(INDEX(ipopt_output!K:K, (ROW()-2)*averages!$U2+2):INDEX(ipopt_output!K:K, (ROW()-2)*averages!$U2+averages!$U2+1)), "") | L2: =IFERROR(_xlfn.STDEV.S(INDEX(ipopt_output!L:L, (ROW()-2)*averages!$U2+2):INDEX(ipopt_output!L:L, (ROW()-2)*averages!$U2+averages!$U2+1)), "") | M2: =IFERROR(_xlfn.STDEV.S(INDEX(ipopt_output!M:M, (ROW()-2)*averages!$U2+2):INDEX(ipopt_output!M:M, (ROW()-2)*averages!$U2+averages!$U2+1)), "") | N2: =IFERROR(_xlfn.STDEV.S(INDEX(ipopt_output!N:N, (ROW()-2)*averages!$U2+2):INDEX(ipopt_output!N:N, (ROW()-2)*averages!$U2+averages!$U2+1)), "") | O2: =IFERROR(_xlfn.STDEV.S(INDEX(ipopt_output!O:O, (ROW()-2)*averages!$U2+2):INDEX(ipopt_output!O:O, (ROW()-2)*averages!$U2+averages!$U2+1)), "") | P2: =IFERROR(_xlfn.STDEV.S(INDEX(ipopt_output!P:P, (ROW()-2)*averages!$U2+2):INDEX(ipopt_output!P:P, (ROW()-2)*averages!$U2+averages!$U2+1)), "") | Q2: =IFERROR(_xlfn.STDEV.S(INDEX(ipopt_output!Q:Q, (ROW()-2)*averages!$U2+2):INDEX(ipopt_output!Q:Q, (ROW()-2)*averages!$U2+averages!$U2+1)), "") | R2: =IFERROR(_xlfn.STDEV.S(INDEX(ipopt_output!R:R, (ROW()-2)*averages!$U2+2):INDEX(ipopt_output!R:R, (ROW()-2)*averages!$U2+averages!$U2+1)), "") | S2: =IFERROR(_xlfn.STDEV.S(INDEX(ipopt_output!S:S, (ROW()-2)*averages!$U2+2):INDEX(ipopt_output!S:S, (ROW()-2)*averages!$U2+averages!$U2+1)), "") | T2: =IFERROR(_xlfn.STDEV.S(INDEX(ipopt_output!T:T, (ROW()-2)*averages!$U2+2):INDEX(ipopt_output!T:T, (ROW()-2)*averages!$U2+averages!$U2+1)), "")
A3: {=INDEX(ipopt_output!A:A, (ROW()-2)*averages!$U3+2)} -> 0 | B3: {=INDEX(ipopt_output!B:B, (ROW()-2)*averages!$U3+2)} -> 0 | C3: =IFERROR(_xlfn.STDEV.S(INDEX(ipopt_output!C:C, (ROW()-2)*averages!$U3+2):INDEX(ipopt_output!C:C, (ROW()-2)*averages!$U3+averages!$U3+1)), "") | D3: =IFERROR(_xlfn.STDEV.S(INDEX(ipopt_output!D:D, (ROW()-2)*averages!$U3+2):INDEX(ipopt_output!D:D, (ROW()-2)*averages!$U3+averages!$U3+1)), "") | E3: =IFERROR(_xlfn.STDEV.S(INDEX(ipopt_output!E:E, (ROW()-2)*averages!$U3+2):INDEX(ipopt_output!E:E, (ROW()-2)*averages!$U3+averages!$U3+1)), "") | F3: =IFERROR(_xlfn.STDEV.S(INDEX(ipopt_output!F:F, (ROW()-2)*averages!$U3+2):INDEX(ipopt_output!F:F, (ROW()-2)*averages!$U3+averages!$U3+1)), "") | G3: =IFERROR(_xlfn.STDEV.S(INDEX(ipopt_output!G:G, (ROW()-2)*averages!$U3+2):INDEX(ipopt_output!G:G, (ROW()-2)*averages!$U3+averages!$U3+1)), "") | H3: =IFERROR(_xlfn.STDEV.S(INDEX(ipopt_output!H:H, (ROW()-2)*averages!$U3+2):INDEX(ipopt_output!H:H, (ROW()-2)*averages!$U3+averages!$U3+1)), "") | I3: =IFERROR(_xlfn.STDEV.S(INDEX(ipopt_output!I:I, (ROW()-2)*averages!$U3+2):INDEX(ipopt_output!I:I, (ROW()-2)*averages!$U3+averages!$U3+1)), "") | J3: =IFERROR(_xlfn.STDEV.S(INDEX(ipopt_output!J:J, (ROW()-2)*averages!$U3+2):INDEX(ipopt_output!J:J, (ROW()-2)*averages!$U3+averages!$U3+1)), "") | K3: =IFERROR(_xlfn.STDEV.S(INDEX(ipopt_output!K:K, (ROW()-2)*averages!$U3+2):INDEX(ipopt_output!K:K, (ROW()-2)*averages!$U3+averages!$U3+1)), "") | L3: =IFERROR(_xlfn.STDEV.S(INDEX(ipopt_output!L:L, (ROW()-2)*averages!$U3+2):INDEX(ipopt_output!L:L, (ROW()-2)*averages!$U3+averages!$U3+1)), "") | M3: =IFERROR(_xlfn.STDEV.S(INDEX(ipopt_output!M:M, (ROW()-2)*averages!$U3+2):INDEX(ipopt_output!M:M, (ROW()-2)*averages!$U3+averages!$U3+1)), "") | N3: =IFERROR(_xlfn.STDEV.S(INDEX(ipopt_output!N:N, (ROW()-2)*averages!$U3+2):INDEX(ipopt_output!N:N, (ROW()-2)*averages!$U3+averages!$U3+1)), "") | O3: =IFERROR(_xlfn.STDEV.S(INDEX(ipopt_output!O:O, (ROW()-2)*averages!$U3+2):INDEX(ipopt_output!O:O, (ROW()-2)*averages!$U3+averages!$U3+1)), "") | P3: =IFERROR(_xlfn.STDEV.S(INDEX(ipopt_output!P:P, (ROW()-2)*averages!$U3+2):INDEX(ipopt_output!P:P, (ROW()-2)*averages!$U3+averages!$U3+1)), "") | Q3: =IFERROR(_xlfn.STDEV.S(INDEX(ipopt_output!Q:Q, (ROW()-2)*averages!$U3+2):INDEX(ipopt_output!Q:Q, (ROW()-2)*averages!$U3+averages!$U3+1)), "") | R3: =IFERROR(_xlfn.STDEV.S(INDEX(ipopt_output!R:R, (ROW()-2)*averages!$U3+2):INDEX(ipopt_output!R:R, (ROW()-2)*averages!$U3+averages!$U3+1)), "") | S3: =IFERROR(_xlfn.STDEV.S(INDEX(ipopt_output!S:S, (ROW()-2)*averages!$U3+2):INDEX(ipopt_output!S:S, (ROW()-2)*averages!$U3+averages!$U3+1)), "") | T3: =IFERROR(_xlfn.STDEV.S(INDEX(ipopt_output!T:T, (ROW()-2)*averages!$U3+2):INDEX(ipopt_output!T:T, (ROW()-2)*averages!$U3+averages!$U3+1)), "")
A4: {=INDEX(ipopt_output!A:A, (ROW()-2)*averages!$U4+2)} -> 0 | B4: {=INDEX(ipopt_output!B:B, (ROW()-2)*averages!$U4+2)} -> 0 | C4: =IFERROR(_xlfn.STDEV.S(INDEX(ipopt_output!C:C, (ROW()-2)*averages!$U4+2):INDEX(ipopt_output!C:C, (ROW()-2)*averages!$U4+averages!$U4+1)), "") | D4: =IFERROR(_xlfn.STDEV.S(INDEX(ipopt_output!D:D, (ROW()-2)*averages!$U4+2):INDEX(ipopt_output!D:D, (ROW()-2)*averages!$U4+averages!$U4+1)), "") | E4: =IFERROR(_xlfn.STDEV.S(INDEX(ipopt_output!E:E, (ROW()-2)*averages!$U4+2):INDEX(ipopt_output!E:E, (ROW()-2)*averages!$U4+averages!$U4+1)), "") | F4: =IFERROR(_xlfn.STDEV.S(INDEX(ipopt_output!F:F, (ROW()-2)*averages!$U4+2):INDEX(ipopt_output!F:F, (ROW()-2)*averages!$U4+averages!$U4+1)), "") | G4: =IFERROR(_xlfn.STDEV.S(INDEX(ipopt_output!G:G, (ROW()-2)*averages!$U4+2):INDEX(ipopt_output!G:G, (ROW()-2)*averages!$U4+averages!$U4+1)), "") | H4: =IFERROR(_xlfn.STDEV.S(INDEX(ipopt_output!H:H, (ROW()-2)*averages!$U4+2):INDEX(ipopt_output!H:H, (ROW()-2)*averages!$U4+averages!$U4+1)), "") | I4: =IFERROR(_xlfn.STDEV.S(INDEX(ipopt_output!I:I, (ROW()-2)*averages!$U4+2):INDEX(ipopt_output!I:I, (ROW()-2)*averages!$U4+averages!$U4+1)), "") | J4: =IFERROR(_xlfn.STDEV.S(INDEX(ipopt_output!J:J, (ROW()-2)*averages!$U4+2):INDEX(ipopt_output!J:J, (ROW()-2)*averages!$U4+averages!$U4+1)), "") | K4: =IFERROR(_xlfn.STDEV.S(INDEX(ipopt_output!K:K, (ROW()-2)*averages!$U4+2):INDEX(ipopt_output!K:K, (ROW()-2)*averages!$U4+averages!$U4+1)), "") | L4: =IFERROR(_xlfn.STDEV.S(INDEX(ipopt_output!L:L, (ROW()-2)*averages!$U4+2):INDEX(ipopt_output!L:L, (ROW()-2)*averages!$U4+averages!$U4+1)), "") | M4: =IFERROR(_xlfn.STDEV.S(INDEX(ipopt_output!M:M, (ROW()-2)*averages!$U4+2):INDEX(ipopt_output!M:M, (ROW()-2)*averages!$U4+averages!$U4+1)), "") | N4: =IFERROR(_xlfn.STDEV.S(INDEX(ipopt_output!N:N, (ROW()-2)*averages!$U4+2):INDEX(ipopt_output!N:N, (ROW()-2)*averages!$U4+averages!$U4+1)), "") | O4: =IFERROR(_xlfn.STDEV.S(INDEX(ipopt_output!O:O, (ROW()-2)*averages!$U4+2):INDEX(ipopt_output!O:O, (ROW()-2)*averages!$U4+averages!$U4+1)), "") | P4: =IFERROR(_xlfn.STDEV.S(INDEX(ipopt_output!P:P, (ROW()-2)*averages!$U4+2):INDEX(ipopt_output!P:P, (ROW()-2)*averages!$U4+averages!$U4+1)), "") | Q4: =IFERROR(_xlfn.STDEV.S(INDEX(ipopt_output!Q:Q, (ROW()-2)*averages!$U4+2):INDEX(ipopt_output!Q:Q, (ROW()-2)*averages!$U4+averages!$U4+1)), "") | R4: =IFERROR(_xlfn.STDEV.S(INDEX(ipopt_output!R:R, (ROW()-2)*averages!$U4+2):INDEX(ipopt_output!R:R, (ROW()-2)*averages!$U4+averages!$U4+1)), "") | S4: =IFERROR(_xlfn.STDEV.S(INDEX(ipopt_output!S:S, (ROW()-2)*averages!$U4+2):INDEX(ipopt_output!S:S, (ROW()-2)*averages!$U4+averages!$U4+1)), "") | T4: =IFERROR(_xlfn.STDEV.S(INDEX(ipopt_output!T:T, (ROW()-2)*averages!$U4+2):INDEX(ipopt_output!T:T, (ROW()-2)*averages!$U4+averages!$U4+1)), "")
A5: {=INDEX(ipopt_output!A:A, (ROW()-2)*averages!$U5+2)} -> 0 | B5: {=INDEX(ipopt_output!B:B, (ROW()-2)*averages!$U5+2)} -> 0 | C5: =IFERROR(_xlfn.STDEV.S(INDEX(ipopt_output!C:C, (ROW()-2)*averages!$U5+2):INDEX(ipopt_output!C:C, (ROW()-2)*averages!$U5+averages!$U5+1)), "") | D5: =IFERROR(_xlfn.STDEV.S(INDEX(ipopt_output!D:D, (ROW()-2)*averages!$U5+2):INDEX(ipopt_output!D:D, (ROW()-2)*averages!$U5+averages!$U5+1)), "") | E5: =IFERROR(_xlfn.STDEV.S(INDEX(ipopt_output!E:E, (ROW()-2)*averages!$U5+2):INDEX(ipopt_output!E:E, (ROW()-2)*averages!$U5+averages!$U5+1)), "") | F5: =IFERROR(_xlfn.STDEV.S(INDEX(ipopt_output!F:F, (ROW()-2)*averages!$U5+2):INDEX(ipopt_output!F:F, (ROW()-2)*averages!$U5+averages!$U5+1)), "") | G5: =IFERROR(_xlfn.STDEV.S(INDEX(ipopt_output!G:G, (ROW()-2)*averages!$U5+2):INDEX(ipopt_output!G:G, (ROW()-2)*averages!$U5+averages!$U5+1)), "") | H5: =IFERROR(_xlfn.STDEV.S(INDEX(ipopt_output!H:H, (ROW()-2)*averages!$U5+2):INDEX(ipopt_output!H:H, (ROW()-2)*averages!$U5+averages!$U5+1)), "") | I5: =IFERROR(_xlfn.STDEV.S(INDEX(ipopt_output!I:I, (ROW()-2)*averages!$U5+2):INDEX(ipopt_output!I:I, (ROW()-2)*averages!$U5+averages!$U5+1)), "") | J5: =IFERROR(_xlfn.STDEV.S(INDEX(ipopt_output!J:J, (ROW()-2)*averages!$U5+2):INDEX(ipopt_output!J:J, (ROW()-2)*averages!$U5+averages!$U5+1)), "") | K5: =IFERROR(_xlfn.STDEV.S(INDEX(ipopt_output!K:K, (ROW()-2)*averages!$U5+2):INDEX(ipopt_output!K:K, (ROW()-2)*averages!$U5+averages!$U5+1)), "") | L5: =IFERROR(_xlfn.STDEV.S(INDEX(ipopt_output!L:L, (ROW()-2)*averages!$U5+2):INDEX(ipopt_output!L:L, (ROW()-2)*averages!$U5+averages!$U5+1)), "") | M5: =IFERROR(_xlfn.STDEV.S(INDEX(ipopt_output!M:M, (ROW()-2)*averages!$U5+2):INDEX(ipopt_output!M:M, (ROW()-2)*averages!$U5+averages!$U5+1)), "") | N5: =IFERROR(_xlfn.STDEV.S(INDEX(ipopt_output!N:N, (ROW()-2)*averages!$U5+2):INDEX(ipopt_output!N:N, (ROW()-2)*averages!$U5+averages!$U5+1)), "") | O5: =IFERROR(_xlfn.STDEV.S(INDEX(ipopt_output!O:O, (ROW()-2)*averages!$U5+2):INDEX(ipopt_output!O:O, (ROW()-2)*averages!$U5+averages!$U5+1)), "") | P5: =IFERROR(_xlfn.STDEV.S(INDEX(ipopt_output!P:P, (ROW()-2)*averages!$U5+2):INDEX(ipopt_output!P:P, (ROW()-2)*averages!$U5+averages!$U5+1)), "") | Q5: =IFERROR(_xlfn.STDEV.S(INDEX(ipopt_output!Q:Q, (ROW()-2)*averages!$U5+2):INDEX(ipopt_output!Q:Q, (ROW()-2)*averages!$U5+averages!$U5+1)), "") | R5: =IFERROR(_xlfn.STDEV.S(INDEX(ipopt_output!R:R, (ROW()-2)*averages!$U5+2):INDEX(ipopt_output!R:R, (ROW()-2)*averages!$U5+averages!$U5+1)), "") | S5: =IFERROR(_xlfn.STDEV.S(INDEX(ipopt_output!S:S, (ROW()-2)*averages!$U5+2):INDEX(ipopt_output!S:S, (ROW()-2)*averages!$U5+averages!$U5+1)), "") | T5: =IFERROR(_xlfn.STDEV.S(INDEX(ipopt_output!T:T, (ROW()-2)*averages!$U5+2):INDEX(ipopt_output!T:T, (ROW()-2)*averages!$U5+averages!$U5+1)), "")
A6: {=INDEX(ipopt_output!A:A, (ROW()-2)*averages!$U6+2)} -> 0 | B6: {=INDEX(ipopt_output!B:B, (ROW()-2)*averages!$U6+2)} -> 0 | C6: =IFERROR(_xlfn.STDEV.S(INDEX(ipopt_output!C:C, (ROW()-2)*averages!$U6+2):INDEX(ipopt_output!C:C, (ROW()-2)*averages!$U6+averages!$U6+1)), "") | D6: =IFERROR(_xlfn.STDEV.S(INDEX(ipopt_output!D:D, (ROW()-2)*averages!$U6+2):INDEX(ipopt_output!D:D, (ROW()-2)*averages!$U6+averages!$U6+1)), "") | E6: =IFERROR(_xlfn.STDEV.S(INDEX(ipopt_output!E:E, (ROW()-2)*averages!$U6+2):INDEX(ipopt_output!E:E, (ROW()-2)*averages!$U6+averages!$U6+1)), "") | F6: =IFERROR(_xlfn.STDEV.S(INDEX(ipopt_output!F:F, (ROW()-2)*averages!$U6+2):INDEX(ipopt_output!F:F, (ROW()-2)*averages!$U6+averages!$U6+1)), "") | G6: =IFERROR(_xlfn.STDEV.S(INDEX(ipopt_output!G:G, (ROW()-2)*averages!$U6+2):INDEX(ipopt_output!G:G, (ROW()-2)*averages!$U6+averages!$U6+1)), "") | H6: =IFERROR(_xlfn.STDEV.S(INDEX(ipopt_output!H:H, (ROW()-2)*averages!$U6+2):INDEX(ipopt_output!H:H, (ROW()-2)*averages!$U6+averages!$U6+1)), "") | I6: =IFERROR(_xlfn.STDEV.S(INDEX(ipopt_output!I:I, (ROW()-2)*averages!$U6+2):INDEX(ipopt_output!I:I, (ROW()-2)*averages!$U6+averages!$U6+1)), "") | J6: =IFERROR(_xlfn.STDEV.S(INDEX(ipopt_output!J:J, (ROW()-2)*averages!$U6+2):INDEX(ipopt_output!J:J, (ROW()-2)*averages!$U6+averages!$U6+1)), "") | K6: =IFERROR(_xlfn.STDEV.S(INDEX(ipopt_output!K:K, (ROW()-2)*averages!$U6+2):INDEX(ipopt_output!K:K, (ROW()-2)*averages!$U6+averages!$U6+1)), "") | L6: =IFERROR(_xlfn.STDEV.S(INDEX(ipopt_output!L:L, (ROW()-2)*averages!$U6+2):INDEX(ipopt_output!L:L, (ROW()-2)*averages!$U6+averages!$U6+1)), "") | M6: =IFERROR(_xlfn.STDEV.S(INDEX(ipopt_output!M:M, (ROW()-2)*averages!$U6+2):INDEX(ipopt_output!M:M, (ROW()-2)*averages!$U6+averages!$U6+1)), "") | N6: =IFERROR(_xlfn.STDEV.S(INDEX(ipopt_output!N:N, (ROW()-2)*averages!$U6+2):INDEX(ipopt_output!N:N, (ROW()-2)*averages!$U6+averages!$U6+1)), "") | O6: =IFERROR(_xlfn.STDEV.S(INDEX(ipopt_output!O:O, (ROW()-2)*averages!$U6+2):INDEX(ipopt_output!O:O, (ROW()-2)*averages!$U6+averages!$U6+1)), "") | P6: =IFERROR(_xlfn.STDEV.S(INDEX(ipopt_output!P:P, (ROW()-2)*averages!$U6+2):INDEX(ipopt_output!P:P, (ROW()-2)*averages!$U6+averages!$U6+1)), "") | Q6: =IFERROR(_xlfn.STDEV.S(INDEX(ipopt_output!Q:Q, (ROW()-2)*averages!$U6+2):INDEX(ipopt_output!Q:Q, (ROW()-2)*averages!$U6+averages!$U6+1)), "") | R6: =IFERROR(_xlfn.STDEV.S(INDEX(ipopt_output!R:R, (ROW()-2)*averages!$U6+2):INDEX(ipopt_output!R:R, (ROW()-2)*averages!$U6+averages!$U6+1)), "") | S6: =IFERROR(_xlfn.STDEV.S(INDEX(ipopt_output!S:S, (ROW()-2)*averages!$U6+2):INDEX(ipopt_output!S:S, (ROW()-2)*averages!$U6+averages!$U6+1)), "") | T6: =IFERROR(_xlfn.STDEV.S(INDEX(ipopt_output!T:T, (ROW()-2)*averages!$U6+2):INDEX(ipopt_output!T:T, (ROW()-2)*averages!$U6+averages!$U6+1)), "")
A7: {=INDEX(ipopt_output!A:A, (ROW()-2)*averages!$U7+2)} -> 0 | B7: {=INDEX(ipopt_output!B:B, (ROW()-2)*averages!$U7+2)} -> 0 | C7: =IFERROR(_xlfn.STDEV.S(INDEX(ipopt_output!C:C, (ROW()-2)*averages!$U7+2):INDEX(ipopt_output!C:C, (ROW()-2)*averages!$U7+averages!$U7+1)), "") | D7: =IFERROR(_xlfn.STDEV.S(INDEX(ipopt_output!D:D, (ROW()-2)*averages!$U7+2):INDEX(ipopt_output!D:D, (ROW()-2)*averages!$U7+averages!$U7+1)), "") | E7: =IFERROR(_xlfn.STDEV.S(INDEX(ipopt_output!E:E, (ROW()-2)*averages!$U7+2):INDEX(ipopt_output!E:E, (ROW()-2)*averages!$U7+averages!$U7+1)), "") | F7: =IFERROR(_xlfn.STDEV.S(INDEX(ipopt_output!F:F, (ROW()-2)*averages!$U7+2):INDEX(ipopt_output!F:F, (ROW()-2)*averages!$U7+averages!$U7+1)), "") | G7: =IFERROR(_xlfn.STDEV.S(INDEX(ipopt_output!G:G, (ROW()-2)*averages!$U7+2):INDEX(ipopt_output!G:G, (ROW()-2)*averages!$U7+averages!$U7+1)), "") | H7: =IFERROR(_xlfn.STDEV.S(INDEX(ipopt_output!H:H, (ROW()-2)*averages!$U7+2):INDEX(ipopt_output!H:H, (ROW()-2)*averages!$U7+averages!$U7+1)), "") | I7: =IFERROR(_xlfn.STDEV.S(INDEX(ipopt_output!I:I, (ROW()-2)*averages!$U7+2):INDEX(ipopt_output!I:I, (ROW()-2)*averages!$U7+averages!$U7+1)), "") | J7: =IFERROR(_xlfn.STDEV.S(INDEX(ipopt_output!J:J, (ROW()-2)*averages!$U7+2):INDEX(ipopt_output!J:J, (ROW()-2)*averages!$U7+averages!$U7+1)), "") | K7: =IFERROR(_xlfn.STDEV.S(INDEX(ipopt_output!K:K, (ROW()-2)*averages!$U7+2):INDEX(ipopt_output!K:K, (ROW()-2)*averages!$U7+averages!$U7+1)), "") | L7: =IFERROR(_xlfn.STDEV.S(INDEX(ipopt_output!L:L, (ROW()-2)*averages!$U7+2):INDEX(ipopt_output!L:L, (ROW()-2)*averages!$U7+averages!$U7+1)), "") | M7: =IFERROR(_xlfn.STDEV.S(INDEX(ipopt_output!M:M, (ROW()-2)*averages!$U7+2):INDEX(ipopt_output!M:M, (ROW()-2)*averages!$U7+averages!$U7+1)), "") | N7: =IFERROR(_xlfn.STDEV.S(INDEX(ipopt_output!N:N, (ROW()-2)*averages!$U7+2):INDEX(ipopt_output!N:N, (ROW()-2)*averages!$U7+averages!$U7+1)), "") | O7: =IFERROR(_xlfn.STDEV.S(INDEX(ipopt_output!O:O, (ROW()-2)*averages!$U7+2):INDEX(ipopt_output!O:O, (ROW()-2)*averages!$U7+averages!$U7+1)), "") | P7: =IFERROR(_xlfn.STDEV.S(INDEX(ipopt_output!P:P, (ROW()-2)*averages!$U7+2):INDEX(ipopt_output!P:P, (ROW()-2)*averages!$U7+averages!$U7+1)), "") | Q7: =IFERROR(_xlfn.STDEV.S(INDEX(ipopt_output!Q:Q, (ROW()-2)*averages!$U7+2):INDEX(ipopt_output!Q:Q, (ROW()-2)*averages!$U7+averages!$U7+1)), "") | R7: =IFERROR(_xlfn.STDEV.S(INDEX(ipopt_output!R:R, (ROW()-2)*averages!$U7+2):INDEX(ipopt_output!R:R, (ROW()-2)*averages!$U7+averages!$U7+1)), "") | S7: =IFERROR(_xlfn.STDEV.S(INDEX(ipopt_output!S:S, (ROW()-2)*averages!$U7+2):INDEX(ipopt_output!S:S, (ROW()-2)*averages!$U7+averages!$U7+1)), "") | T7: =IFERROR(_xlfn.STDEV.S(INDEX(ipopt_output!T:T, (ROW()-2)*averages!$U7+2):INDEX(ipopt_output!T:T, (ROW()-2)*averages!$U7+averages!$U7+1)), "")
A8: {=INDEX(ipopt_output!A:A, (ROW()-2)*averages!$U8+2)} -> 0 | B8: {=INDEX(ipopt_output!B:B, (ROW()-2)*averages!$U8+2)} -> 0 | C8: =IFERROR(_xlfn.STDEV.S(INDEX(ipopt_output!C:C, (ROW()-2)*averages!$U8+2):INDEX(ipopt_output!C:C, (ROW()-2)*averages!$U8+averages!$U8+1)), "") | D8: =IFERROR(_xlfn.STDEV.S(INDEX(ipopt_output!D:D, (ROW()-2)*averages!$U8+2):INDEX(ipopt_output!D:D, (ROW()-2)*averages!$U8+averages!$U8+1)), "") | E8: =IFERROR(_xlfn.STDEV.S(INDEX(ipopt_output!E:E, (ROW()-2)*averages!$U8+2):INDEX(ipopt_output!E:E, (ROW()-2)*averages!$U8+averages!$U8+1)), "") | F8: =IFERROR(_xlfn.STDEV.S(INDEX(ipopt_output!F:F, (ROW()-2)*averages!$U8+2):INDEX(ipopt_output!F:F, (ROW()-2)*averages!$U8+averages!$U8+1)), "") | G8: =IFERROR(_xlfn.STDEV.S(INDEX(ipopt_output!G:G, (ROW()-2)*averages!$U8+2):INDEX(ipopt_output!G:G, (ROW()-2)*averages!$U8+averages!$U8+1)), "") | H8: =IFERROR(_xlfn.STDEV.S(INDEX(ipopt_output!H:H, (ROW()-2)*averages!$U8+2):INDEX(ipopt_output!H:H, (ROW()-2)*averages!$U8+averages!$U8+1)), "") | I8: =IFERROR(_xlfn.STDEV.S(INDEX(ipopt_output!I:I, (ROW()-2)*averages!$U8+2):INDEX(ipopt_output!I:I, (ROW()-2)*averages!$U8+averages!$U8+1)), "") | J8: =IFERROR(_xlfn.STDEV.S(INDEX(ipopt_output!J:J, (ROW()-2)*averages!$U8+2):INDEX(ipopt_output!J:J, (ROW()-2)*averages!$U8+averages!$U8+1)), "") | K8: =IFERROR(_xlfn.STDEV.S(INDEX(ipopt_output!K:K, (ROW()-2)*averages!$U8+2):INDEX(ipopt_output!K:K, (ROW()-2)*averages!$U8+averages!$U8+1)), "") | L8: =IFERROR(_xlfn.STDEV.S(INDEX(ipopt_output!L:L, (ROW()-2)*averages!$U8+2):INDEX(ipopt_output!L:L, (ROW()-2)*averages!$U8+averages!$U8+1)), "") | M8: =IFERROR(_xlfn.STDEV.S(INDEX(ipopt_output!M:M, (ROW()-2)*averages!$U8+2):INDEX(ipopt_output!M:M, (ROW()-2)*averages!$U8+averages!$U8+1)), "") | N8: =IFERROR(_xlfn.STDEV.S(INDEX(ipopt_output!N:N, (ROW()-2)*averages!$U8+2):INDEX(ipopt_output!N:N, (ROW()-2)*averages!$U8+averages!$U8+1)), "") | O8: =IFERROR(_xlfn.STDEV.S(INDEX(ipopt_output!O:O, (ROW()-2)*averages!$U8+2):INDEX(ipopt_output!O:O, (ROW()-2)*averages!$U8+averages!$U8+1)), "") | P8: =IFERROR(_xlfn.STDEV.S(INDEX(ipopt_output!P:P, (ROW()-2)*averages!$U8+2):INDEX(ipopt_output!P:P, (ROW()-2)*averages!$U8+averages!$U8+1)), "") | Q8: =IFERROR(_xlfn.STDEV.S(INDEX(ipopt_output!Q:Q, (ROW()-2)*averages!$U8+2):INDEX(ipopt_output!Q:Q, (ROW()-2)*averages!$U8+averages!$U8+1)), "") | R8: =IFERROR(_xlfn.STDEV.S(INDEX(ipopt_output!R:R, (ROW()-2)*averages!$U8+2):INDEX(ipopt_output!R:R, (ROW()-2)*averages!$U8+averages!$U8+1)), "") | S8: =IFERROR(_xlfn.STDEV.S(INDEX(ipopt_output!S:S, (ROW()-2)*averages!$U8+2):INDEX(ipopt_output!S:S, (ROW()-2)*averages!$U8+averages!$U8+1)), "") | T8: =IFERROR(_xlfn.STDEV.S(INDEX(ipopt_output!T:T, (ROW()-2)*averages!$U8+2):INDEX(ipopt_output!T:T, (ROW()-2)*averages!$U8+averages!$U8+1)), "")
A9: {=INDEX(ipopt_output!A:A, (ROW()-2)*averages!$U9+2)} -> 0 | B9: {=INDEX(ipopt_output!B:B, (ROW()-2)*averages!$U9+2)} -> 0 | C9: =IFERROR(_xlfn.STDEV.S(INDEX(ipopt_output!C:C, (ROW()-2)*averages!$U9+2):INDEX(ipopt_output!C:C, (ROW()-2)*averages!$U9+averages!$U9+1)), "") | D9: =IFERROR(_xlfn.STDEV.S(INDEX(ipopt_output!D:D, (ROW()-2)*averages!$U9+2):INDEX(ipopt_output!D:D, (ROW()-2)*averages!$U9+averages!$U9+1)), "") | E9: =IFERROR(_xlfn.STDEV.S(INDEX(ipopt_output!E:E, (ROW()-2)*averages!$U9+2):INDEX(ipopt_output!E:E, (ROW()-2)*averages!$U9+averages!$U9+1)), "") | F9: =IFERROR(_xlfn.STDEV.S(INDEX(ipopt_output!F:F, (ROW()-2)*averages!$U9+2):INDEX(ipopt_output!F:F, (ROW()-2)*averages!$U9+averages!$U9+1)), "") | G9: =IFERROR(_xlfn.STDEV.S(INDEX(ipopt_output!G:G, (ROW()-2)*averages!$U9+2):INDEX(ipopt_output!G:G, (ROW()-2)*averages!$U9+averages!$U9+1)), "") | H9: =IFERROR(_xlfn.STDEV.S(INDEX(ipopt_output!H:H, (ROW()-2)*averages!$U9+2):INDEX(ipopt_output!H:H, (ROW()-2)*averages!$U9+averages!$U9+1)), "") | I9: =IFERROR(_xlfn.STDEV.S(INDEX(ipopt_output!I:I, (ROW()-2)*averages!$U9+2):INDEX(ipopt_output!I:I, (ROW()-2)*averages!$U9+averages!$U9+1)), "") | J9: =IFERROR(_xlfn.STDEV.S(INDEX(ipopt_output!J:J, (ROW()-2)*averages!$U9+2):INDEX(ipopt_output!J:J, (ROW()-2)*averages!$U9+averages!$U9+1)), "") | K9: =IFERROR(_xlfn.STDEV.S(INDEX(ipopt_output!K:K, (ROW()-2)*averages!$U9+2):INDEX(ipopt_output!K:K, (ROW()-2)*averages!$U9+averages!$U9+1)), "") | L9: =IFERROR(_xlfn.STDEV.S(INDEX(ipopt_output!L:L, (ROW()-2)*averages!$U9+2):INDEX(ipopt_output!L:L, (ROW()-2)*averages!$U9+averages!$U9+1)), "") | M9: =IFERROR(_xlfn.STDEV.S(INDEX(ipopt_output!M:M, (ROW()-2)*averages!$U9+2):INDEX(ipopt_output!M:M, (ROW()-2)*averages!$U9+averages!$U9+1)), "") | N9: =IFERROR(_xlfn.STDEV.S(INDEX(ipopt_output!N:N, (ROW()-2)*averages!$U9+2):INDEX(ipopt_output!N:N, (ROW()-2)*averages!$U9+averages!$U9+1)), "") | O9: =IFERROR(_xlfn.STDEV.S(INDEX(ipopt_output!O:O, (ROW()-2)*averages!$U9+2):INDEX(ipopt_output!O:O, (ROW()-2)*averages!$U9+averages!$U9+1)), "") | P9: =IFERROR(_xlfn.STDEV.S(INDEX(ipopt_output!P:P, (ROW()-2)*averages!$U9+2):INDEX(ipopt_output!P:P, (ROW()-2)*averages!$U9+averages!$U9+1)), "") | Q9: =IFERROR(_xlfn.STDEV.S(INDEX(ipopt_output!Q:Q, (ROW()-2)*averages!$U9+2):INDEX(ipopt_output!Q:Q, (ROW()-2)*averages!$U9+averages!$U9+1)), "") | R9: =IFERROR(_xlfn.STDEV.S(INDEX(ipopt_output!R:R, (ROW()-2)*averages!$U9+2):INDEX(ipopt_output!R:R, (ROW()-2)*averages!$U9+averages!$U9+1)), "") | S9: =IFERROR(_xlfn.STDEV.S(INDEX(ipopt_output!S:S, (ROW()-2)*averages!$U9+2):INDEX(ipopt_output!S:S, (ROW()-2)*averages!$U9+averages!$U9+1)), "") | T9: =IFERROR(_xlfn.STDEV.S(INDEX(ipopt_output!T:T, (ROW()-2)*averages!$U9+2):INDEX(ipopt_output!T:T, (ROW()-2)*averages!$U9+averages!$U9+1)), "")
A10: {=INDEX(ipopt_output!A:A, (ROW()-2)*averages!$U10+2)} -> 0 | B10: {=INDEX(ipopt_output!B:B, (ROW()-2)*averages!$U10+2)} -> 0 | C10: =IFERROR(_xlfn.STDEV.S(INDEX(ipopt_output!C:C, (ROW()-2)*averages!$U10+2):INDEX(ipopt_output!C:C, (ROW()-2)*averages!$U10+averages!$U10+1)), "") | D10: =IFERROR(_xlfn.STDEV.S(INDEX(ipopt_output!D:D, (ROW()-2)*averages!$U10+2):INDEX(ipopt_output!D:D, (ROW()-2)*averages!$U10+averages!$U10+1)), "") | E10: =IFERROR(_xlfn.STDEV.S(INDEX(ipopt_output!E:E, (ROW()-2)*averages!$U10+2):INDEX(ipopt_output!E:E, (ROW()-2)*averages!$U10+averages!$U10+1)), "") | F10: =IFERROR(_xlfn.STDEV.S(INDEX(ipopt_output!F:F, (ROW()-2)*averages!$U10+2):INDEX(ipopt_output!F:F, (ROW()-2)*averages!$U10+averages!$U10+1)), "") | G10: =IFERROR(_xlfn.STDEV.S(INDEX(ipopt_output!G:G, (ROW()-2)*averages!$U10+2):INDEX(ipopt_output!G:G, (ROW()-2)*averages!$U10+averages!$U10+1)), "") | H10: =IFERROR(_xlfn.STDEV.S(INDEX(ipopt_output!H:H, (ROW()-2)*averages!$U10+2):INDEX(ipopt_output!H:H, (ROW()-2)*averages!$U10+averages!$U10+1)), "") | I10: =IFERROR(_xlfn.STDEV.S(INDEX(ipopt_output!I:I, (ROW()-2)*averages!$U10+2):INDEX(ipopt_output!I:I, (ROW()-2)*averages!$U10+averages!$U10+1)), "") | J10: =IFERROR(_xlfn.STDEV.S(INDEX(ipopt_output!J:J, (ROW()-2)*averages!$U10+2):INDEX(ipopt_output!J:J, (ROW()-2)*averages!$U10+averages!$U10+1)), "") | K10: =IFERROR(_xlfn.STDEV.S(INDEX(ipopt_output!K:K, (ROW()-2)*averages!$U10+2):INDEX(ipopt_output!K:K, (ROW()-2)*averages!$U10+averages!$U10+1)), "") | L10: =IFERROR(_xlfn.STDEV.S(INDEX(ipopt_output!L:L, (ROW()-2)*averages!$U10+2):INDEX(ipopt_output!L:L, (ROW()-2)*averages!$U10+averages!$U10+1)), "") | M10: =IFERROR(_xlfn.STDEV.S(INDEX(ipopt_output!M:M, (ROW()-2)*averages!$U10+2):INDEX(ipopt_output!M:M, (ROW()-2)*averages!$U10+averages!$U10+1)), "") | N10: =IFERROR(_xlfn.STDEV.S(INDEX(ipopt_output!N:N, (ROW()-2)*averages!$U10+2):INDEX(ipopt_output!N:N, (ROW()-2)*averages!$U10+averages!$U10+1)), "") | O10: =IFERROR(_xlfn.STDEV.S(INDEX(ipopt_output!O:O, (ROW()-2)*averages!$U10+2):INDEX(ipopt_output!O:O, (ROW()-2)*averages!$U10+averages!$U10+1)), "") | P10: =IFERROR(_xlfn.STDEV.S(INDEX(ipopt_output!P:P, (ROW()-2)*averages!$U10+2):INDEX(ipopt_output!P:P, (ROW()-2)*averages!$U10+averages!$U10+1)), "") | Q10: =IFERROR(_xlfn.STDEV.S(INDEX(ipopt_output!Q:Q, (ROW()-2)*averages!$U10+2):INDEX(ipopt_output!Q:Q, (ROW()-2)*averages!$U10+averages!$U10+1)), "") | R10: =IFERROR(_xlfn.STDEV.S(INDEX(ipopt_output!R:R, (ROW()-2)*averages!$U10+2):INDEX(ipopt_output!R:R, (ROW()-2)*averages!$U10+averages!$U10+1)), "") | S10: =IFERROR(_xlfn.STDEV.S(INDEX(ipopt_output!S:S, (ROW()-2)*averages!$U10+2):INDEX(ipopt_output!S:S, (ROW()-2)*averages!$U10+averages!$U10+1)), "") | T10: =IFERROR(_xlfn.STDEV.S(INDEX(ipopt_output!T:T, (ROW()-2)*averages!$U10+2):INDEX(ipopt_output!T:T, (ROW()-2)*averages!$U10+averages!$U10+1)), "")
A11: {=INDEX(ipopt_output!A:A, (ROW()-2)*averages!$U11+2)} -> 0 | B11: {=INDEX(ipopt_output!B:B, (ROW()-2)*averages!$U11+2)} -> 0 | C11: =IFERROR(_xlfn.STDEV.S(INDEX(ipopt_output!C:C, (ROW()-2)*averages!$U11+2):INDEX(ipopt_output!C:C, (ROW()-2)*averages!$U11+averages!$U11+1)), "") | D11: =IFERROR(_xlfn.STDEV.S(INDEX(ipopt_output!D:D, (ROW()-2)*averages!$U11+2):INDEX(ipopt_output!D:D, (ROW()-2)*averages!$U11+averages!$U11+1)), "") | E11: =IFERROR(_xlfn.STDEV.S(INDEX(ipopt_output!E:E, (ROW()-2)*averages!$U11+2):INDEX(ipopt_output!E:E, (ROW()-2)*averages!$U11+averages!$U11+1)), "") | F11: =IFERROR(_xlfn.STDEV.S(INDEX(ipopt_output!F:F, (ROW()-2)*averages!$U11+2):INDEX(ipopt_output!F:F, (ROW()-2)*averages!$U11+averages!$U11+1)), "") | G11: =IFERROR(_xlfn.STDEV.S(INDEX(ipopt_output!G:G, (ROW()-2)*averages!$U11+2):INDEX(ipopt_output!G:G, (ROW()-2)*averages!$U11+averages!$U11+1)), "") | H11: =IFERROR(_xlfn.STDEV.S(INDEX(ipopt_output!H:H, (ROW()-2)*averages!$U11+2):INDEX(ipopt_output!H:H, (ROW()-2)*averages!$U11+averages!$U11+1)), "") | I11: =IFERROR(_xlfn.STDEV.S(INDEX(ipopt_output!I:I, (ROW()-2)*averages!$U11+2):INDEX(ipopt_output!I:I, (ROW()-2)*averages!$U11+averages!$U11+1)), "") | J11: =IFERROR(_xlfn.STDEV.S(INDEX(ipopt_output!J:J, (ROW()-2)*averages!$U11+2):INDEX(ipopt_output!J:J, (ROW()-2)*averages!$U11+averages!$U11+1)), "") | K11: =IFERROR(_xlfn.STDEV.S(INDEX(ipopt_output!K:K, (ROW()-2)*averages!$U11+2):INDEX(ipopt_output!K:K, (ROW()-2)*averages!$U11+averages!$U11+1)), "") | L11: =IFERROR(_xlfn.STDEV.S(INDEX(ipopt_output!L:L, (ROW()-2)*averages!$U11+2):INDEX(ipopt_output!L:L, (ROW()-2)*averages!$U11+averages!$U11+1)), "") | M11: =IFERROR(_xlfn.STDEV.S(INDEX(ipopt_output!M:M, (ROW()-2)*averages!$U11+2):INDEX(ipopt_output!M:M, (ROW()-2)*averages!$U11+averages!$U11+1)), "") | N11: =IFERROR(_xlfn.STDEV.S(INDEX(ipopt_output!N:N, (ROW()-2)*averages!$U11+2):INDEX(ipopt_output!N:N, (ROW()-2)*averages!$U11+averages!$U11+1)), "") | O11: =IFERROR(_xlfn.STDEV.S(INDEX(ipopt_output!O:O, (ROW()-2)*averages!$U11+2):INDEX(ipopt_output!O:O, (ROW()-2)*averages!$U11+averages!$U11+1)), "") | P11: =IFERROR(_xlfn.STDEV.S(INDEX(ipopt_output!P:P, (ROW()-2)*averages!$U11+2):INDEX(ipopt_output!P:P, (ROW()-2)*averages!$U11+averages!$U11+1)), "") | Q11: =IFERROR(_xlfn.STDEV.S(INDEX(ipopt_output!Q:Q, (ROW()-2)*averages!$U11+2):INDEX(ipopt_output!Q:Q, (ROW()-2)*averages!$U11+averages!$U11+1)), "") | R11: =IFERROR(_xlfn.STDEV.S(INDEX(ipopt_output!R:R, (ROW()-2)*averages!$U11+2):INDEX(ipopt_output!R:R, (ROW()-2)*averages!$U11+averages!$U11+1)), "") | S11: =IFERROR(_xlfn.STDEV.S(INDEX(ipopt_output!S:S, (ROW()-2)*averages!$U11+2):INDEX(ipopt_output!S:S, (ROW()-2)*averages!$U11+averages!$U11+1)), "") | T11: =IFERROR(_xlfn.STDEV.S(INDEX(ipopt_output!T:T, (ROW()-2)*averages!$U11+2):INDEX(ipopt_output!T:T, (ROW()-2)*averages!$U11+averages!$U11+1)), "")
A12: {=INDEX(ipopt_output!A:A, (ROW()-2)*averages!$U12+2)} -> 0 | B12: {=INDEX(ipopt_output!B:B, (ROW()-2)*averages!$U12+2)} -> 0 | C12: =IFERROR(_xlfn.STDEV.S(INDEX(ipopt_output!C:C, (ROW()-2)*averages!$U12+2):INDEX(ipopt_output!C:C, (ROW()-2)*averages!$U12+averages!$U12+1)), "") | D12: =IFERROR(_xlfn.STDEV.S(INDEX(ipopt_output!D:D, (ROW()-2)*averages!$U12+2):INDEX(ipopt_output!D:D, (ROW()-2)*averages!$U12+averages!$U12+1)), "") | E12: =IFERROR(_xlfn.STDEV.S(INDEX(ipopt_output!E:E, (ROW()-2)*averages!$U12+2):INDEX(ipopt_output!E:E, (ROW()-2)*averages!$U12+averages!$U12+1)), "") | F12: =IFERROR(_xlfn.STDEV.S(INDEX(ipopt_output!F:F, (ROW()-2)*averages!$U12+2):INDEX(ipopt_output!F:F, (ROW()-2)*averages!$U12+averages!$U12+1)), "") | G12: =IFERROR(_xlfn.STDEV.S(INDEX(ipopt_output!G:G, (ROW()-2)*averages!$U12+2):INDEX(ipopt_output!G:G, (ROW()-2)*averages!$U12+averages!$U12+1)), "") | H12: =IFERROR(_xlfn.STDEV.S(INDEX(ipopt_output!H:H, (ROW()-2)*averages!$U12+2):INDEX(ipopt_output!H:H, (ROW()-2)*averages!$U12+averages!$U12+1)), "") | I12: =IFERROR(_xlfn.STDEV.S(INDEX(ipopt_output!I:I, (ROW()-2)*averages!$U12+2):INDEX(ipopt_output!I:I, (ROW()-2)*averages!$U12+averages!$U12+1)), "") | J12: =IFERROR(_xlfn.STDEV.S(INDEX(ipopt_output!J:J, (ROW()-2)*averages!$U12+2):INDEX(ipopt_output!J:J, (ROW()-2)*averages!$U12+averages!$U12+1)), "") | K12: =IFERROR(_xlfn.STDEV.S(INDEX(ipopt_output!K:K, (ROW()-2)*averages!$U12+2):INDEX(ipopt_output!K:K, (ROW()-2)*averages!$U12+averages!$U12+1)), "") | L12: =IFERROR(_xlfn.STDEV.S(INDEX(ipopt_output!L:L, (ROW()-2)*averages!$U12+2):INDEX(ipopt_output!L:L, (ROW()-2)*averages!$U12+averages!$U12+1)), "") | M12: =IFERROR(_xlfn.STDEV.S(INDEX(ipopt_output!M:M, (ROW()-2)*averages!$U12+2):INDEX(ipopt_output!M:M, (ROW()-2)*averages!$U12+averages!$U12+1)), "") | N12: =IFERROR(_xlfn.STDEV.S(INDEX(ipopt_output!N:N, (ROW()-2)*averages!$U12+2):INDEX(ipopt_output!N:N, (ROW()-2)*averages!$U12+averages!$U12+1)), "") | O12: =IFERROR(_xlfn.STDEV.S(INDEX(ipopt_output!O:O, (ROW()-2)*averages!$U12+2):INDEX(ipopt_output!O:O, (ROW()-2)*averages!$U12+averages!$U12+1)), "") | P12: =IFERROR(_xlfn.STDEV.S(INDEX(ipopt_output!P:P, (ROW()-2)*averages!$U12+2):INDEX(ipopt_output!P:P, (ROW()-2)*averages!$U12+averages!$U12+1)), "") | Q12: =IFERROR(_xlfn.STDEV.S(INDEX(ipopt_output!Q:Q, (ROW()-2)*averages!$U12+2):INDEX(ipopt_output!Q:Q, (ROW()-2)*averages!$U12+averages!$U12+1)), "") | R12: =IFERROR(_xlfn.STDEV.S(INDEX(ipopt_output!R:R, (ROW()-2)*averages!$U12+2):INDEX(ipopt_output!R:R, (ROW()-2)*averages!$U12+averages!$U12+1)), "") | S12: =IFERROR(_xlfn.STDEV.S(INDEX(ipopt_output!S:S, (ROW()-2)*averages!$U12+2):INDEX(ipopt_output!S:S, (ROW()-2)*averages!$U12+averages!$U12+1)), "") | T12: =IFERROR(_xlfn.STDEV.S(INDEX(ipopt_output!T:T, (ROW()-2)*averages!$U12+2):INDEX(ipopt_output!T:T, (ROW()-2)*averages!$U12+averages!$U12+1)), "")
